Workbook

Sheet 占比汇总
B1: 2019 | C1: 2018 | D1: 2017 | E1: 2016 | F1: 2015 | G1: 2014 | H1: 2013 | I1: 2012 | J1: 2011 | K1: 2010 | L1: 2009 | M1: 2008
A2: 全 国 | B2: 0.46479283 | C2: 0.46414023 | D2: 0.4569 | E2: 0.4496527 | F2: 0.46788163 | G2: 0.47637678 | H2: 0.47382314 | I2: 0.47910739 | J2: 0.41531206 | K2: 0.51538842 | L2: 0.51616097 | M2: 0.51451054
A3: 北 京 | B3: 0.19166549 | C3: 0.24711825 | D3: 0.29391 | E3: 0.34070639 | F3: 0.27008116 | G3: 0.44836196 | H3: 0.52414983 | I3: 0.53293734 | J3: 0.49472035 | K3: 0.65449647 | L3: 0.70916905 | M3: 0.62630121
A4: 天 津 | B4: 0.41498234 | C4: 0.55765083 | D4: 0.38908 | E4: 0.22050382 | F4: 0.52122758 | G4: 0.53544545 | H4: 0.54305345 | I4: 0.58477218 | J4: 0.48333964 | K4: 0.64035001 | L4: 0.62901723 | M4: 0.60548769
A5: 河 北 | B5: 0.53781409 | C5: 0.52729185 | D5: 0.53773 | E5: 0.54816168 | F5: 0.5477965 | G5: 0.5556733 | H5: 0.58579308 | I5: 0.58390767 | J5: 0.5168018 | K5: 0.60886516 | L5: 0.63070179 | M5: 0.64175458
A6: 山 西 | B6: 0.38084085 | C6: 0.34626613 | D6: 0.34313 | E6: 0.33999545 | F6: 0.3788065 | G6: 0.40264026 | H6: 0.4244362 | I6: 0.48946973 | J6: 0.46393335 | K6: 0.55292735 | L6: 0.58465011 | M6: 0.60188447
A7: 内蒙古 | B7: 0.67682324 | C7: 0.67023021 | D7: 0.68193 | E7: 0.69363202 | F7: 0.69627036 | G7: 0.69334936 | H7: 0.64978332 | I7: 0.64262183 | J7: 0.61447857 | K7: 0.64050857 | L7: 0.69431732 | M7: 0.74267399
A8: 辽 宁 | B8: 0.58926058 | C8: 0.58779819 | D8: 0.56564 | E8: 0.54347197 | F8: 0.55075305 | G8: 0.55006166 | H8: 0.53554688 | I8: 0.55696071 | J8: 0.50558094 | K8: 0.58833004 | L8: 0.57837197 | M8: 0.56469822
A9: 吉 林 | B9: 0.42224629 | C9: 0.549647 | D9: 0.5097 | E9: 0.46974507 | F9: 0.47571146 | G9: 0.48096636 | H9: 0.44669494 | I9: 0.42900424 | J9: 0.40112239 | K9: 0.44069731 | L9: 0.38891648 | M9: 0.46530175
A10: 黑龙江 | B10: 0.35077594 | C10: 0.48569451 | D10: 0.47248 | E10: 0.45926837 | F10: 0.45255765 | G10: 0.45219167 | H10: 0.47052569 | I10: 0.47048748 | J10: 0.42481267 | K10: 0.58721575 | L10: 0.61962982 | M10: 0.58064516
A11: 上 海 | B11: 0.33361874 | C11: 0.32792555 | D11: 0.32979 | E11: 0.33165001 | F11: 0.30426855 | G11: 0.28450488 | H11: 0.33641058 | I11: 0.34542231 | J11: 0.28905838 | K11: 0.50676006 | L11: 0.50171545 | M11: 0.54278059
A12: 江 苏 | B12: 0.335727 | C12: 0.33711579 | D12: 0.3455 | E12: 0.35387764 | F12: 0.35112256 | G12: 0.37028646 | H12: 0.38106835 | I12: 0.39444594 | J12: 0.28408437 | K12: 0.40312169 | L12: 0.41214206 | M12: 0.41507814
A13: 浙 江 | B13: 0.28901955 | C13: 0.29936238 | D13: 0.30101 | E13: 0.30265979 | F13: 0.29648599 | G13: 0.29233256 | H13: 0.27720683 | I13: 0.27487711 | J13: 0.19946992 | K13: 0.27821709 | L13: 0.29329433 | M13: 0.29833001
... A33: 新 疆 | B33: 0.20007613 | C33: 0.72947257 | D33: 0.70085 | E33: 0.67221825 | F33: 0.67194616 | G33: 0.62906351 | H33: 0.60703589 | I33: 0.57831018 | J33: 0.45704239 | K33: 0.59751571 | L33: 0.64807976 | M33: 0.66482348

Sheet 绿色信贷-计算结果
A1: 地区 | B1: 2020 | C1: 2019 | D1: 2018 | E1: 2017 | F1: 2016 | G1: 2015 | H1: 2014 | I1: 2013 | J1: 2012 | K1: 2011 | L1: 2010 | M1: 2009 | N1: 2008 | O1: 2007 | P1: 2006 | Q1: 2005 | R1: 2021 | S1: 2022 | T1: 2004
A2: 全 国 | B2: 0.4793952 | C2: ='2014-2020计算过程'!T5 -> 0.46479283 | D2: ='2014-2020计算过程'!AD5 -> 0.46414023 | E2: ='2017年插值法填充'!I3 -> 0.45683879 | F2: ='2014-2020计算过程'!AM5 -> 0.4496527 | G2: ='2014-2020计算过程'!AV5 -> 0.46788163 | H2: ='2014-2020计算过程'!BE5 -> 0.47637678 | I2: ='2014-2020计算过程'!BN5 -> 0.47382314 | J2: ='2006-2013计算过程'!I4 -> 0.47910739 | K2: ='2006-2013计算过程'!R4 -> 0.4881305 | L2: ='2006-2013计算过程'!AA4 -> 0.51538842 | M2: ='2006-2013计算过程'!AJ4 -> 0.51616097 | N2: ='2006-2013计算过程'!AS4 -> 0.51451054 | O2: ='2006-2013计算过程'!BC4 -> 0.50697882 | P2: 0.50283176 | Q2: 0.48616801 | R2: 0.48312757 | S2: 0.48426716
A3: 北 京 | B3: 0.28426019 | C3: ='2014-2020计算过程'!T6 -> 0.19166549 | D3: ='2014-2020计算过程'!AD6 -> 0.24711825 | E3: ='2017年插值法填充'!I4 -> 0.28751926 | F3: ='2014-2020计算过程'!AM6 -> 0.34070639 | G3: ='2014-2020计算过程'!AV6 -> 0.27008116 | H3: ='2014-2020计算过程'!BE6 -> 0.44836196 | I3: ='2014-2020计算过程'!BN6 -> 0.52414983 | J3: ='2006-2013计算过程'!I5 -> 0.53293734 | K3: ='2006-2013计算过程'!R5 -> 0.52314922 | L3: ='2006-2013计算过程'!AA5 -> 0.65449647 | M3: ='2006-2013计算过程'!AJ5 -> 0.70916905 | N3: ='2006-2013计算过程'!AS5 -> 0.62630121 | O3: ='2006-2013计算过程'!BC5 -> 0.52759602 | P3: 0.51976125 | Q3: 0.55506769 | R3: 0.43590763 | S3: 0.48913452
A4: 天 津 | B4: 0.48796312 | C4: ='2014-2020计算过程'!T7 -> 0.41498234 | D4: ='2014-2020计算过程'!AD7 -> 0.55765083 | E4: ='2017年插值法填充'!I5 -> 0.30823477 | F4: ='2014-2020计算过程'!AM7 -> 0.22050382 | G4: ='2014-2020计算过程'!AV7 -> 0.52122758 | H4: ='2014-2020计算过程'!BE7 -> 0.53544545 | I4: ='2014-2020计算过程'!BN7 -> 0.54305345 | J4: ='2006-2013计算过程'!I6 -> 0.58477218 | K4: ='2006-2013计算过程'!R6 -> 0.58721444 | L4: ='2006-2013计算过程'!AA6 -> 0.64035001 | M4: ='2006-2013计算过程'!AJ6 -> 0.62901723 | N4: ='2006-2013计算过程'!AS6 -> 0.60548769 | O4: ='2006-2013计算过程'!BC6 -> 0.62886259 | P4: 0.56677966 | Q4: 0.4397518 | R4: 0.51656122 | S4: 0.56773895
A5: 河 北 | B5: 0.61479767 | C5: ='2014-2020计算过程'!T8 -> 0.53781409 | D5: ='2014-2020计算过程'!AD8 -> 0.52729185 | E5: ='2017年插值法填充'!I6 -> 0.53709668 | F5: ='2014-2020计算过程'!AM8 -> 0.54816168 | G5: ='2014-2020计算过程'!AV8 -> 0.5477965 | H5: ='2014-2020计算过程'!BE8 -> 0.5556733 | I5: ='2014-2020计算过程'!BN8 -> 0.58579308 | J5: ='2006-2013计算过程'!I7 -> 0.58390767 | K5: ='2006-2013计算过程'!R7 -> 0.55936937 | L5: ='2006-2013计算过程'!AA7 -> 0.60886516 | M5: ='2006-2013计算过程'!AJ7 -> 0.63070179 | N5: ='2006-2013计算过程'!AS7 -> 0.64175458 | O5: ='2006-2013计算过程'!BC7 -> 0.63844966 | P5: 0.61898259 | Q5: 0.60669775 | R5: 0.61378457 | S5: 0.60142552
A6: 山 西 | B6: 0.30824838 | C6: ='2014-2020计算过程'!T9 -> 0.38084085 | D6: ='2014-2020计算过程'!AD9 -> 0.34626613 | E6: ='2017年插值法填充'!I7 -> 0.34338865 | F6: ='2014-2020计算过程'!AM9 -> 0.33999545 | G6: ='2014-2020计算过程'!AV9 -> 0.3788065 | H6: ='2014-2020计算过程'!BE9 -> 0.40264026 | I6: ='2014-2020计算过程'!BN9 -> 0.4244362 | J6: ='2006-2013计算过程'!I8 -> 0.48946973 | K6: ='2006-2013计算过程'!R8 -> 0.52227688 | L6: ='2006-2013计算过程'!AA8 -> 0.55292735 | M6: ='2006-2013计算过程'!AJ8 -> 0.58465011 | N6: ='2006-2013计算过程'!AS8 -> 0.60188447 | O6: ='2006-2013计算过程'!BC8 -> 0.63569016 | P6: 0.66380117 | Q6: 0.65798769 | R6: 0.29675484 | S6: 0.32786194
A7: 内蒙古 | B7: 0.68503144 | C7: ='2014-2020计算过程'!T10 -> 0.67682324 | D7: ='2014-2020计算过程'!AD10 -> 0.67023021 | E7: ='2017年插值法填充'!I8 -> 0.68116739 | F7: ='2014-2020计算过程'!AM10 -> 0.69363202 | G7: ='2014-2020计算过程'!AV10 -> 0.69627036 | H7: ='2014-2020计算过程'!BE10 -> 0.69334936 | I7: ='2014-2020计算过程'!BN10 -> 0.64978332 | J7: ='2006-2013计算过程'!I9 -> 0.64262183 | K7: ='2006-2013计算过程'!R9 -> 0.66526445 | L7: ='2006-2013计算过程'!AA9 -> 0.64050857 | M7: ='2006-2013计算过程'!AJ9 -> 0.69431732 | N7: ='2006-2013计算过程'!AS9 -> 0.74267399 | O7: ='2006-2013计算过程'!BC9 -> 0.69294317 | P7: 0.70580527 | Q7: 0.702571 | R7: 0.66211396 | S7: 0.6588238
A8: 辽 宁 | B8: 0.58171086 | C8: ='2014-2020计算过程'!T11 -> 0.58926058 | D8: ='2014-2020计算过程'!AD11 -> 0.58779819 | E8: ='2017年插值法填充'!I9 -> 0.56610984 | F8: ='2014-2020计算过程'!AM11 -> 0.54347197 | G8: ='2014-2020计算过程'!AV11 -> 0.55075305 | H8: ='2014-2020计算过程'!BE11 -> 0.55006166 | I8: ='2014-2020计算过程'!BN11 -> 0.53554688 | J8: ='2006-2013计算过程'!I10 -> 0.55696071 | K8: ='2006-2013计算过程'!R10 -> 0.55567958 | L8: ='2006-2013计算过程'!AA10 -> 0.58833004 | M8: ='2006-2013计算过程'!AJ10 -> 0.57837197 | N8: ='2006-2013计算过程'!AS10 -> 0.56469822 | O8: ='2006-2013计算过程'!BC10 -> 0.58045626 | P8: 0.59238322 | Q8: 0.59294471 | R8: 0.6351137 | S8: 0.60588203
A9: 吉 林 | B9: 0.45376607 | C9: ='2014-2020计算过程'!T12 -> 0.42224629 | D9: ='2014-2020计算过程'!AD12 -> 0.549647 | E9: ='2017年插值法填充'!I10 -> 0.50386441 | F9: ='2014-2020计算过程'!AM12 -> 0.46974507 | G9: ='2014-2020计算过程'!AV12 -> 0.47571146 | H9: ='2014-2020计算过程'!BE12 -> 0.48096636 | I9: ='2014-2020计算过程'!BN12 -> 0.44669494 | J9: ='2006-2013计算过程'!I11 -> 0.42900424 | K9: ='2006-2013计算过程'!R11 -> 0.45176376 | L9: ='2006-2013计算过程'!AA11 -> 0.44069731 | M9: ='2006-2013计算过程'!AJ11 -> 0.38891648 | N9: ='2006-2013计算过程'!AS11 -> 0.46530175 | O9: ='2006-2013计算过程'!BC11 -> 0.40679245 | P9: 0.46833821 | Q9: 0.49098532 | R9: 0.37374571 | S9: 0.54253011
A10: 黑龙江 | B10: 0.39928523 | C10: ='2014-2020计算过程'!T13 -> 0.35077594 | D10: ='2014-2020计算过程'!AD13 -> 0.48569451 | E10: ='2017年插值法填充'!I11 -> 0.4725148 | F10: ='2014-2020计算过程'!AM13 -> 0.45926837 | G10: ='2014-2020计算过程'!AV13 -> 0.45255765 | H10: ='2014-2020计算过程'!BE13 -> 0.45219167 | I10: ='2014-2020计算过程'!BN13 -> 0.47052569 | J10: ='2006-2013计算过程'!I12 -> 0.47048748 | K10: ='2006-2013计算过程'!R12 -> 0.46295981 | L10: ='2006-2013计算过程'!AA12 -> 0.58721575 | M10: ='2006-2013计算过程'!AJ12 -> 0.61962982 | N10: ='2006-2013计算过程'!AS12 -> 0.58064516 | O10: ='2006-2013计算过程'!BC12 -> 0.64533333 | P10: 0.58048349 | Q10: 0.4840213 | R10: 0.43206802 | S10: 0.45552006
A11: 上 海 | B11: 0.32764427 | C11: ='2014-2020计算过程'!T14 -> 0.33361874 | D11: ='2014-2020计算过程'!AD14 -> 0.32792555 | E11: ='2017年插值法填充'!I12 -> 0.32976401 | F11: ='2014-2020计算过程'!AM14 -> 0.33165001 | G11: ='2014-2020计算过程'!AV14 -> 0.30426855 | H11: ='2014-2020计算过程'!BE14 -> 0.28450488 | I11: ='2014-2020计算过程'!BN14 -> 0.33641058 | J11: ='2006-2013计算过程'!I13 -> 0.34542231 | K11: ='2006-2013计算过程'!R13 -> 0.38686622 | L11: ='2006-2013计算过程'!AA13 -> 0.50676006 | M11: ='2006-2013计算过程'!AJ13 -> 0.50171545 | N11: ='2006-2013计算过程'!AS13 -> 0.54278059 | O11: ='2006-2013计算过程'!BC13 -> 0.47465399 | P11: 0.45296136 | Q11: 0.37793891 | R11: 0.37231256 | S11: 0.32806493
A12: 江 苏 | B12: 0.33832838 | C12: ='2014-2020计算过程'!T15 -> 0.335727 | D12: ='2014-2020计算过程'!AD15 -> 0.33711579 | E12: ='2017年插值法填充'!I13 -> 0.34573438 | F12: ='2014-2020计算过程'!AM15 -> 0.35387764 | G12: ='2014-2020计算过程'!AV15 -> 0.35112256 | H12: ='2014-2020计算过程'!BE15 -> 0.37028646 | I12: ='2014-2020计算过程'!BN15 -> 0.38106835 | J12: ='2006-2013计算过程'!I14 -> 0.39444594 | K12: ='2006-2013计算过程'!R14 -> 0.39653275 | L12: ='2006-2013计算过程'!AA14 -> 0.40312169 | M12: ='2006-2013计算过程'!AJ14 -> 0.41214206 | N12: ='2006-2013计算过程'!AS14 -> 0.41507814 | O12: ='2006-2013计算过程'!BC14 -> 0.40819526 | P12: 0.41704848 | Q12: 0.40818508 | R12: 0.34019069 | S12: 0.34562092
A13: 浙 江 | B13: 0.30213628 | C13: ='2014-2020计算过程'!T16 -> 0.28901955 | D13: ='2014-2020计算过程'!AD16 -> 0.29936238 | E13: ='2017年插值法填充'!I14 -> 0.30105408 | F13: ='2014-2020计算过程'!AM16 -> 0.30265979 | G13: ='2014-2020计算过程'!AV16 -> 0.29648599 | H13: ='2014-2020计算过程'!BE16 -> 0.29233256 | I13: ='2014-2020计算过程'!BN16 -> 0.27720683 | J13: ='2006-2013计算过程'!I15 -> 0.27487711 | K13: ='2006-2013计算过程'!R15 -> 0.27742108 | L13: ='2006-2013计算过程'!AA15 -> 0.27821709 | M13: ='2006-2013计算过程'!AJ15 -> 0.29329433 | N13: ='2006-2013计算过程'!AS15 -> 0.29833001 | O13: ='2006-2013计算过程'!BC15 -> 0.28670882 | P13: 0.30107792 | Q13: 0.30075773 | R13: 0.30007437 | S13: 0.3139365
... A33: 新 疆 | B33: 0.69995168 | C33: ='2014-2020计算过程'!T36 -> 0.20007613 | D33: ='2014-2020计算过程'!AD36 -> 0.72947257 | E33: ='2017年插值法填充'!I34 -> 0.70084332 | F33: ='2014-2020计算过程'!AM36 -> 0.67221825 | G33: ='2014-2020计算过程'!AV36 -> 0.67194616 | H33: ='2014-2020计算过程'!BE36 -> 0.62906351 | I33: ='2014-2020计算过程'!BN36 -> 0.60703589 | J33: ='2006-2013计算过程'!I35 -> 0.57831018 | K33: ='2006-2013计算过程'!R35 -> 0.58002281 | L33: ='2006-2013计算过程'!AA35 -> 0.59751571 | M33: ='2006-2013计算过程'!AJ35 -> 0.64807976 | N33: ='2006-2013计算过程'!AS35 -> 0.66482348 | O33: ='2006-2013计算过程'!BC35 -> 0.6285862 | P33: 0.54131248 | Q33: 0.5538099 | R33: 0.71051589 | S33: 0.70066115
S36: 更多数据：关注公众号【马克数据网】

Sheet Sheet3
A1: 地 区 | B1: 总 | C1: 化学 | D1: 石油 | E1: 电力热力 | F1: 黑色金属 | G1: 有色金属 | H1: 非金属 | I1: 年份
A2: 全 国 | B2: 12061.89 | C2: 853.72 | D2: 387.56 | E2: 2517.47 | F2: 740.99 | G2: 597.73 | H2: 508.81 | I2: 2019 | K2: 求和项:非金属 | L2: 列标签
A3: 北 京 | B3: 283.88 | C3: 2.02 | D3: 2.05 | E3: 42.4 | F3: 1.32 | G3: 0.19 | H3: 6.43 | I3: 2019 | K3: 行标签 | L3: 安 徽 | M3: 北 京 | N3: 福 建 | O3: 甘 肃 | P3: 广 东 | Q3: 广 西 | R3: 贵 州 | S3: 海 南 | T3: 河 北 | U3: 河 南 | V3: 黑龙江 | W3: 湖 北 | X3: 湖 南 | Y3: 吉 林 | Z3: 江 苏 | AA3: 江 西 | AB3: 辽 宁 | AC3: 内蒙古 | AD3: 宁 夏 | AE3: 青 海 | AF3: 全 国 | AG3: 山 东 | AH3: 山 西 | AI3: 陕 西 | AJ3: 上 海 | AK3: 四 川 | AL3: 天 津 | AM3: 西 藏 | AN3: 新 疆 | AO3: 云 南 | AP3: 浙 江 | AQ3: 重 庆
A4: 天 津 | B4: 133.09 | C4: 15.87 | D4: 2.69 | E4: 17.89 | F4: 9.6 | G4: 6.37 | H4: 2.81 | I4: 2019 | K4: 2007 | L4: 6.36 | M4: 2.57 | N4: 7.79 | O4: 2.09 | P4: 12.53 | Q4: 2.59 | R4: 1.06 | S4: 0.39 | T4: 10.8 | U4: 15.49 | V4: 1.29 | W4: 6.19 | X4: 4.21 | Y4: 3.11 | Z4: 17.54 | AA4: 3.19 | AB4: 9.06 | AC4: 3.27 | AD4: 1.07 | AE4: 0.15 | AF4: 191.75 | AG4: 31.1 | AH4: 4.75 | AI4: 2.94 | AJ4: 4.2 | AK4: 7.35 | AL4: 1.82 | AM4: 0.16 | AN4: 2.43 | AO4: 3.18 | AP4: 19.05 | AQ4: 4.01
A5: 河 北 | B5: 569.1 | C5: 27.48 | D5: 18.52 | E5: 79.95 | F5: 148.95 | G5: 6.36 | H5: 24.81 | I5: 2019 | K5: 2008 | L5: 8.46 | M5: 4.1 | N5: 10.06 | O5: 2.48 | P5: 14.89 | Q5: 3.65 | R5: 1.18 | S5: 0.58 | T5: 13.72 | U5: 18.85 | V5: 1.28 | W5: 8.9 | X5: 5.21 | Y5: 5.06 | Z5: 24.51 | AA5: 5.92 | AB5: 11.31 | AC5: 5.36 | AD5: 1.51 | AE5: 0.34 | AF5: 252.86 | AG5: 40.62 | AH5: 5.14 | AI5: 3.69 | AJ5: 4.68 | AK5: 9.8 | AL5: 2.75 | AM5: 0.1 | AN5: 3.13 | AO5: 4.22 | AP5: 24.95 | AQ5: 6.41
A6: 山 西 | B6: 691.68 | C6: 41.95 | D6: 34.43 | E6: 103.26 | F6: 49 | G6: 21.75 | H6: 13.03 | I6: 2019 | K6: 2009 | L6: 8.32 | M6: 2.95 | N6: 10.41 | O6: 2.21 | P6: 13.5 | Q6: 3.6 | R6: 1.4 | S6: 0.48 | T6: 13.18 | U6: 22.11 | V6: 1.31 | W6: 7.61 | X6: 7.31 | Y6: 6.81 | Z6: 20.25 | AA6: 5.73 | AB6: 12.43 | AC6: 5.52 | AD6: 1.52 | AE6: 0.63 | AF6: 246.62 | AG6: 35.57 | AH6: 5.9 | AI6: 3.91 | AJ6: 3.76 | AK6: 11.03 | AL6: 1.93 | AM6: 0.11 | AN6: 3.54 | AO6: 4.29 | AP6: 23.86 | AQ6: 5.43
A7: 内蒙古 | B7: 445.36 | C7: 63.44 | D7: 11.44 | E7: 151.27 | F7: 28.77 | G7: 35.26 | H7: 11.25 | I7: 2019 | K7: 2010 | L7: 11.15 | M7: 2.17 | N7: 11.44 | O7: 2.71 | P7: 14.31 | Q7: 5.59 | R7: 3.15 | S7: 0.86 | T7: 15.87 | U7: 27.09 | V7: 1.99 | W7: 14.63 | X7: 9.11 | Y7: 7.7 | Z7: 24.34 | AA7: 6.4 | AB7: 14.86 | AC7: 8 | AD7: 2.45 | AE7: 1.18 | AF7: 305.75 | AG7: 38.86 | AH7: 6.68 | AI7: 4.73 | AJ7: 3.56 | AK7: 18.91 | AL7: 2.28 | AM7: 0.13 | AN7: 4.95 | AO7: 4.61 | AP7: 28.95 | AQ7: 7.09
A8: 辽 宁 | B8: 447.51 | C8: 30.68 | D8: 38.06 | E8: 69.84 | F8: 90.66 | G8: 15.71 | H8: 18.75 | I8: 2019 | K8: 2011 | L8: 15.23 | M8: 4.7 | N8: 17.32 | O8: 4.21 | P8: 22.44 | Q8: 7.58 | R8: 4.63 | S8: 0.95 | T8: 28.48 | U8: 38.85 | V8: 2.98 | W8: 18.84 | X8: 13.21 | Y8: 12.15 | Z8: 36.06 | AA8: 10.02 | AB8: 19.97 | AC8: 8.01 | AD8: 2.93 | AE8: 1.44 | AF8: 433.7 | AG8: 47.99 | AH8: 9.72 | AI8: 6.34 | AJ8: 5.34 | AK8: 26.44 | AL8: 2.71 | AM8: 0.19 | AN8: 6.8 | AO8: 6.34 | AP8: 41.35 | AQ8: 10.48
A9: 吉 林 | B9: 147.71 | C9: 7.72 | D9: 0.95 | E9: 35.75 | F9: 9.3 | G9: 1.11 | H9: 7.54 | I9: 2019 | K9: 2012 | L9: 18.76 | M9: 6.29 | N9: 21.4 | O9: 5.9 | P9: 26.33 | Q9: 9.6 | R9: 8.32 | S9: 1.27 | T9: 34.15 | U9: 46.61 | V9: 5.47 | W9: 24.49 | X9: 16.48 | Y9: 17.49 | Z9: 46.42 | AA9: 12.32 | AB9: 28.03 | AC9: 10.23 | AD9: 3.9 | AE9: 1.21 | AF9: 543.59 | AG9: 57.58 | AH9: 10.73 | AI9: 7.67 | AJ9: 6.67 | AK9: 29.78 | AL9: 4.58 | AM9: 0.18 | AN9: 10.58 | AO9: 8.74 | AP9: 46.09 | AQ9: 16.29
A10: 黑龙江 | B10: 155.94 | C10: 4.58 | D10: 5.71 | E10: 35.98 | F10: 3.78 | G10: 1.64 | H10: 3.01 | I10: 2019 | K10: 2013 | L10: 20.94 | M10: 7.83 | N10: 24.67 | O10: 7.87 | P10: 27.89 | Q10: 10.63 | R10: 11.58 | S10: 2.38 | T10: 39.4 | U10: 51.05 | V10: 7.37 | W10: 29.07 | X10: 22.72 | Y10: 23.44 | Z10: 52.14 | AA10: 15.09 | AB10: 22.93 | AC10: 12.78 | AD10: 3.35 | AE10: 2.81 | AF10: 616.7 | AG10: 62.95 | AH10: 11.81 | AI10: 9.66 | AJ10: 6.2 | AK10: 34.25 | AL10: 4.57 | AM10: 0.19 | AN10: 16.35 | AO10: 10.75 | AP10: 47.36 | AQ10: 16.69
A11: 上 海 | B11: 198.55 | C11: 13.37 | D11: 4.18 | E11: 19.18 | F11: 23.45 | G11: 3.14 | H11: 2.92 | I11: 2019 | K11: 2014 | L11: 22.52 | M11: 7.76 | N11: 26.03 | O11: 7.74 | P11: 34.12 | Q11: 11.43 | R11: 14.3 | S11: 2.44 | T11: 45.34 | U11: 57.52 | V11: 7.97 | W11: 37.05 | X11: 25.36 | Y11: 28.88 | Z11: 53.59 | AA11: 17.24 | AB11: 21.55 | AC11: 12.33 | AD11: 3.36 | AE11: 3.8 | AF11: 702.35 | AG11: 67.08 | AH11: 14.05 | AI11: 13.42 | AJ11: 5.91 | AK11: 55.08 | AL11: 4.82 | AM11: 0.13 | AN11: 20.48 | AO11: 13.52 | AP11: 48.06 | AQ11: 19.47
A12: 江 苏 | B12: 1022.14 | C12: 91.03 | D12: 6.62 | E12: 119.94 | F12: 60.44 | G12: 29.37 | H12: 35.76 | I12: 2019 | K12: 2015 | L12: 22.2 | M12: 6.97 | N12: 25.78 | O12: 7.1 | P12: 34.09 | Q12: 12.36 | R12: 16.41 | S12: 2.27 | T12: 40.68 | U12: 62.37 | V12: 5.75 | W12: 24.38 | X12: 27.55 | Y12: 26.51 | Z12: 46.02 | AA12: 17.48 | AB12: 18.8 | AC12: 12.36 | AD12: 3.32 | AE12: 3.26 | AF12: 646.36 | AG12: 64.67 | AH12: 13.72 | AI12: 10.14 | AJ12: 4.09 | AK12: 37.64 | AL12: 3.64 | AM12: 0.25 | AN12: 18.33 | AO12: 13.63 | AP12: 44.47 | AQ12: 20.15
A13: 浙 江 | B13: 863.99 | C13: 61.22 | D13: 7.25 | E13: 114.25 | F13: 12.3 | G13: 20.49 | H13: 34.2 | I13: 2019 | K13: 2016 | L13: 20.2 | M13: 6.87 | N13: 24.94 | O13: 7.48 | P13: 33.57 | Q13: 11.91 | R13: 14.91 | S13: 2.3 | T13: 35.24 | U13: 63.9 | V13: 4.61 | W13: 27.43 | X13: 24.11 | Y13: 21.78 | Z13: 43.78 | AA13: 16.25 | AB13: 14.75 | AC13: 12.03 | AD13: 2.44 | AE13: 5.09 | AF13: 596.17 | AG13: 60.48 | AH13: 10.45 | AI13: 9.83 | AJ13: 2.69 | AK13: 37.27 | AL13: 2.8 | AM13: 0.31 | AN13: 16.87 | AO13: 9.35 | AP13: 35.39 | AQ13: 17.14
A14: 安 徽 | B14: 346.78 | C14: 26.1 | D14: 2.41 | E14: 61.32 | F14: 11.65 | G14: 12.62 | H14: 20.16 | I14: 2019 | K14: 2017
A15: 福 建 | B15: 394.85 | C15: 24.98 | D15: 11.21 | E15: 77.24 | F15: 8.73 | G15: 29.91 | H15: 25.4 | I15: 2019 | K15: 2018 | L15: 19.99 | M15: 25.49 | N15: 26.27 | O15: 7.29 | P15: 31.99 | Q15: 9.62 | R15: 13.64 | S15: 2.75 | T15: 24.62 | U15: 50.46 | V15: 4.37 | W15: 20.07 | X15: 20.24 | Y15: 8.2 | Z15: 34.89 | AA15: 14.91 | AB15: 19.17 | AC15: 8.67 | AD15: 2.36 | AE15: 5.48 | AF15: 540.11 | AG15: 47.52 | AH15: 12.5 | AI15: 11.81 | AJ15: 2.75 | AK15: 34.35 | AL15: 3.44 | AM15: 0.51 | AN15: 15.56 | AO15: 11.48 | AP15: 33.62 | AQ15: 16.09
A16: 江 西 | B16: 201.78 | C16: 9.18 | D16: 4.11 | E16: 27.72 | F16: 6.27 | G16: 18.35 | H16: 15.57 | I16: 2019 | K16: 2019 | L16: 20.16 | M16: 6.43 | N16: 25.4 | O16: 6.48 | P16: 35.05 | Q16: 10.11 | R16: 12.95 | S16: 2.07 | T16: 24.81 | U16: 43.56 | V16: 3.01 | W16: 17.46 | X16: 21.08 | Y16: 7.54 | Z16: 35.76 | AA16: 15.57 | AB16: 18.75 | AC16: 11.25 | AD16: 2.21 | AE16: 4.37 | AF16: 508.81 | AG16: 39.26 | AH16: 13.03 | AI16: 11.99 | AJ16: 2.92 | AK16: 34.31 | AL16: 2.81 | AM16: 0.45 | AO16: 9.86 | AP16: 34.2 | AQ16: 17.61
A17: 山 东 | B17: 1097.01 | C17: 107.3 | D17: 93.07 | E17: 174.61 | F17: 55.09 | G17: 82.98 | H17: 39.26 | I17: 2019
A18: 河 南 | B18: 666.15 | C18: 58.36 | D18: 18.42 | E18: 94.08 | F18: 19.15 | G18: 88.31 | H18: 43.56 | I18: 2019
A19: 湖 北 | B19: 392.1 | C19: 34.64 | D19: 2.38 | E19: 71.48 | F19: 23.14 | G19: 6.17 | H19: 17.46 | I19: 2019
A20: 湖 南 | B20: 282.11 | C20: 13.53 | D20: 2.18 | E20: 59.11 | F20: 8.26 | G20: 13.85 | H20: 21.08 | I20: 2019
A21: 广 东 | B21: 976.7 | C21: 38.01 | D21: 16.2 | E21: 181.12 | F21: 18.62 | G21: 18.95 | H21: 35.05 | I21: 2019
A22: 广 西 | B22: 210.86 | C22: 5.15 | D22: 2.08 | E22: 66.19 | F22: 14.96 | G22: 24.5 | H22: 10.11 | I22: 2019
A23: 海 南 | B23: 45.14 | C23: 3.43 | D23: 2.61 | E23: 18.88 | G23: 0.01 | H23: 2.07 | I23: 2019
A24: 重 庆 | B24: 193.85 | C24: 13.42 | D24: 0.43 | E24: 38.25 | F24: 4.35 | G24: 9 | H24: 17.61 | I24: 2019
A25: 四 川 | B25: 604.18 | C25: 25.09 | D25: 3.05 | E25: 211.39 | F25: 45.58 | G25: 5.95 | H25: 34.31 | I25: 2019
A26: 贵 州 | B26: 195.34 | C26: 23.36 | D26: 2.49 | E26: 88.4 | F26: 3.87 | G26: 8.1 | H26: 12.95 | I26: 2019
A27: 云 南 | B27: 332.17 | C27: 16.17 | D27: 5.37 | E27: 189.31 | F27: 10.49 | G27: 32.25 | H27: 9.86 | I27: 2019
A28: 西 藏 | B28: 10 | C28: 0.03 | E28: 4.84 | H28: 0.45 | I28: 2019
A29: 陕 西 | B29: 373.81 | C29: 35.66 | D29: 67.42 | E29: 54.97 | F29: 9.68 | G29: 14.59 | H29: 11.99 | I29: 2019
A30: 甘 肃 | B30: 193.49 | C30: 3.94 | D30: 5.07 | E30: 69.43 | F30: 27.69 | G30: 34.01 | H30: 6.48 | I30: 2019
A31: 青 海 | B31: 114.75 | C31: 12.1 | D31: 0.41 | E31: 49.4 | F31: 7.55 | G31: 24.66 | H31: 4.37 | I31: 2019
A32: 宁 夏 | B32: 156.64 | C32: 15.7 | D32: 6.66 | E32: 63.33 | F32: 20.58 | G32: 5.23 | H32: 2.21 | I32: 2019
A33: 新 疆 | B33: 315.23 | D33: 10.07 | E33: 7.75 | F33: 26.9 | G33: 18.35 | I33: 2019
A34: 全 国 | B34: 12303.48 | C34: 949.2 | D34: 403.57 | E34: 2252.15 | F34: 870.18 | G34: 695.33 | H34: 540.11 | I34: 2018
A35: 北 京 | B35: 294.96 | C35: 2.92 | D35: 1.44 | E35: 41.29 | F35: 1.36 | G35: 0.39 | H35: 25.49 | I35: 2018
A36: 天 津 | B36: 162.27 | C36: 16.55 | D36: 2.25 | E36: 15.19 | F36: 46.39 | G36: 6.67 | H36: 3.44 | I36: 2018
A37: 河 北 | B37: 570.5 | C37: 28.66 | D37: 17.51 | E37: 66.6 | F37: 157.12 | G37: 6.31 | H37: 24.62 | I37: 2018
A38: 山 西 | B38: 719.36 | C38: 40.61 | D38: 38.99 | E38: 89.55 | F38: 44.85 | G38: 22.59 | H38: 12.5 | I38: 2018
A39: 内蒙古 | B39: 445.25 | C39: 65.03 | D39: 11.19 | E39: 145.37 | F39: 34.11 | G39: 34.05 | H39: 8.67 | I39: 2018
A40: 辽 宁 | B40: 466.98 | C40: 35.76 | D40: 34.32 | E40: 68.1 | F40: 103.34 | G40: 13.8 | H40: 19.17 | I40: 2018
...

Sheet 2014-2020计算过程
A1: 2021年鉴(统计2020年绿色信贷水平) | L1: 2020年鉴(统计2019年绿色信贷水平) | W1: 2018经济普查 | AF1: 2017中国工业统计年鉴 | AO1: 2016中国工业统计年鉴 | AX1: 2015中国工业统计年鉴 | BG1: 2014中国工业统计年鉴
A2: 地 区 | B2: 总 | C2: 化学 | D2: 石油 | E2: 电力热力 | F2: 黑色金属 | G2: 有色金属 | H2: 非金属 | L2: 地 区 | M2: 总 | N2: 化学 | O2: 石油 | P2: 电力热力 | Q2: 黑色金属 | R2: 有色金属 | S2: 非金属 | W2: 总 | X2: 化学 | Y2: 石油 | Z2: 电力热力 | AA2: 黑色金属 | AB2: 有色金属 | AC2: 非金属 | AF2: 总 | AG2: 化学 | AH2: 石油 | AI2: 电力热力 | AJ2: 黑色金属 | AK2: 有色金属 | AL2: 非金属 | AO2: 总 | AP2: 化学 | AQ2: 石油 | AR2: 电力热力 | AS2: 黑色金属 | AT2: 有色金属 | AU2: 非金属 | AX2: 总 | AY2: 化学 | AZ2: 石油 | BA2: 电力热力 | BB2: 黑色金属 | BC2: 有色金属 | BD2: 非金属 | BG2: 总 | BH2: 化学 | BI2: 石油 | BJ2: 电力热力 | BK2: 黑色金属 | BL2: 有色金属 | BM2: 非金属
B3: 利息费用 | C3: 利息费用 | D3: 利息费用 | E3: 利息费用 | F3: 利息费用 | G3: 利息费用 | H3: 利息费用 | M3: 利息费用 | N3: 利息费用 | O3: 利息费用 | P3: 利息费用 | Q3: 利息费用 | R3: 利息费用 | S3: 利息费用 | W3: 利息支出 | X3: 利息支出 | Y3: 利息支出 | Z3: 利息支出 | AA3: 利息支出 | AB3: 利息支出 | AC3: 利息支出
AF4: 利息支出 | AG4: 利息支出 | AH4: 利息支出 | AI4: 利息支出 | AJ4: 利息支出 | AK4: 利息支出 | AL4: 利息支出 | AO4: 利息支出 | AP4: 利息支出 | AQ4: 利息支出 | AR4: 利息支出 | AS4: 利息支出 | AT4: 利息支出 | AU4: 利息支出 | AX4: 利息支出 | AY4: 利息支出 | AZ4: 利息支出 | BA4: 利息支出 | BB4: 利息支出 | BC4: 利息支出 | BD4: 利息支出 | BG4: 利息支出 | BH4: 利息支出 | BI4: 利息支出 | BJ4: 利息支出 | BK4: 利息支出 | BL4: 利息支出 | BM4: 利息支出
A5: 全 国 | B5: 11141.58 | C5: 766.61 | D5: 365.62 | E5: 2579.07 | F5: 635.66 | G5: 549.78 | H5: 444.48 | I5: =SUM(C5:H5)/B5 -> 0.4793952 | L5: 全 国 | M5: 12061.89 | N5: 853.72 | O5: 387.56 | P5: 2517.47 | Q5: 740.99 | R5: 597.73 | S5: 508.81 | T5: =SUM(N5:S5)/M5 -> 0.46479283 | W5: 12303.48 | X5: 949.2 | Y5: 403.57 | Z5: 2252.15 | AA5: 870.18 | AB5: 695.33 | AC5: 540.11 | AD5: =SUM(X5:AC5)/W5 -> 0.46414023 | AF5: 12505.14 | AG5: 1054.09 | AH5: 353.1 | AI5: 2066.79 | AJ5: 920.28 | AK5: 632.54 | AL5: 596.17 | AM5: =SUM(AG5:AL5)/AF5 -> 0.4496527 | AO5: 13029.77 | AP5: 1126.07 | AQ5: 390.98 | AR5: 2225.79 | AS5: 1029.14 | AT5: 678.05 | AU5: 646.36 | AV5: =SUM(AP5:AU5)/AO5 -> 0.46788163 | AX5: 13577.53 | AY5: 1137.09 | AZ5: 435.27 | BA5: 2357.48 | BB5: 1169.14 | BC5: 666.69 | BD5: 702.35 | BE5: =SUM(AY5:BD5)/AX5 -> 0.47637678 | BG5: 12346.02 | BH5: 988.7 | BI5: 376.46 | BJ5: 2149.48 | BK5: 1120.46 | BL5: 598.03 | BM5: 616.7 | BN5: =SUM(BH5:BM5)/BG5 -> 0.47382314
A6: 北 京 | B6: 309.47 | C6: 1.6 | D6: 2.35 | E6: 74.71 | F6: 1.21 | G6: 0.22 | H6: 7.88 | I6: =SUM(C6:H6)/B6 -> 0.28426019 | L6: 北 京 | M6: 283.88 | N6: 2.02 | O6: 2.05 | P6: 42.4 | Q6: 1.32 | R6: 0.19 | S6: 6.43 | T6: =SUM(N6:S6)/M6 -> 0.19166549 | W6: 294.96 | X6: 2.92 | Y6: 1.44 | Z6: 41.29 | AA6: 1.36 | AB6: 0.39 | AC6: 25.49 | AD6: =SUM(X6:AC6)/W6 -> 0.24711825 | AF6: 224.24 | AG6: 4.82 | AH6: 1.91 | AI6: 60.79 | AJ6: 1.54 | AK6: 0.47 | AL6: 6.87 | AM6: =SUM(AG6:AL6)/AF6 -> 0.34070639 | AO6: 178.65 | AP6: 4.93 | AQ6: 2.55 | AR6: 31.58 | AS6: 1.7 | AT6: 0.52 | AU6: 6.97 | AV6: =SUM(AP6:AU6)/AO6 -> 0.27008116 | AX6: 264.34 | AY6: 6.29 | AZ6: 2.9 | BA6: 98.19 | BB6: 2.82 | BC6: 0.56 | BD6: 7.76 | BE6: =SUM(AY6:BD6)/AX6 -> 0.44836196 | BG6: 243.48 | BH6: 5.43 | BI6: 2.85 | BJ6: 108.3 | BK6: 2.55 | BL6: 0.66 | BM6: 7.83 | BN6: =SUM(BH6:BM6)/BG6 -> 0.52414983
A7: 天 津 | B7: 117.14 | C7: 15.69 | D7: 2.61 | E7: 18.78 | F7: 9.81 | G7: 7.67 | H7: 2.6 | I7: =SUM(C7:H7)/B7 -> 0.48796312 | L7: 天 津 | M7: 133.09 | N7: 15.87 | O7: 2.69 | P7: 17.89 | Q7: 9.6 | R7: 6.37 | S7: 2.81 | T7: =SUM(N7:S7)/M7 -> 0.41498234 | W7: 162.27 | X7: 16.55 | Y7: 2.25 | Z7: 15.19 | AA7: 46.39 | AB7: 6.67 | AC7: 3.44 | AD7: =SUM(X7:AC7)/W7 -> 0.55765083 | AF7: 461.67 | AG7: 18.54 | AH7: 3.86 | AI7: 15.06 | AJ7: 57.42 | AK7: 4.12 | AL7: 2.8 | AM7: =SUM(AG7:AL7)/AF7 -> 0.22050382 | AO7: 223.53 | AP7: 22.2 | AQ7: 7.18 | AR7: 16.87 | AS7: 61.74 | AT7: 4.88 | AU7: 3.64 | AV7: =SUM(AP7:AU7)/AO7 -> 0.52122758 | AX7: 241.78 | AY7: 27.38 | AZ7: 4.32 | BA7: 16.96 | BB7: 70.79 | BC7: 5.19 | BD7: 4.82 | BE7: =SUM(AY7:BD7)/AX7 -> 0.53544545 | BG7: 224.14 | BH7: 19.56 | BI7: 7.52 | BJ7: 18.81 | BK7: 66.14 | BL7: 5.12 | BM7: 4.57 | BN7: =SUM(BH7:BM7)/BG7 -> 0.54305345
A8: 河 北 | B8: 539.95 | C8: 30.1 | D8: 21.95 | E8: 91.1 | F8: 162.3 | G8: 4.97 | H8: 21.54 | I8: =SUM(C8:H8)/B8 -> 0.61479767 | L8: 河 北 | M8: 569.1 | N8: 27.48 | O8: 18.52 | P8: 79.95 | Q8: 148.95 | R8: 6.36 | S8: 24.81 | T8: =SUM(N8:S8)/M8 -> 0.53781409 | W8: 570.5 | X8: 28.66 | Y8: 17.51 | Z8: 66.6 | AA8: 157.12 | AB8: 6.31 | AC8: 24.62 | AD8: =SUM(X8:AC8)/W8 -> 0.52729185 | AF8: 503.72 | AG8: 23.29 | AH8: 18.31 | AI8: 58.99 | AJ8: 134.54 | AK8: 5.75 | AL8: 35.24 | AM8: =SUM(AG8:AL8)/AF8 -> 0.54816168 | AO8: 555.48 | AP8: 32.3 | AQ8: 22.17 | AR8: 62.84 | AS8: 140.6 | AT8: 5.7 | AU8: 40.68 | AV8: =SUM(AP8:AU8)/AO8 -> 0.5477965 | AX8: 613.4 | AY8: 31.89 | AZ8: 22.22 | BA8: 69.15 | BB8: 165.99 | BC8: 6.26 | BD8: 45.34 | BE8: =SUM(AY8:BD8)/AX8 -> 0.5556733 | BG8: 587.46 | BH8: 27.93 | BI8: 22.4 | BJ8: 71.92 | BK8: 176.94 | BL8: 5.54 | BM8: 39.4 | BN8: =SUM(BH8:BM8)/BG8 -> 0.58579308
A9: 山 西 | B9: 863.2 | C9: 40.9 | D9: 43.92 | E9: 105.48 | F9: 40.51 | G9: 23.98 | H9: 11.29 | I9: =SUM(C9:H9)/B9 -> 0.30824838 | L9: 山 西 | M9: 691.68 | N9: 41.95 | O9: 34.43 | P9: 103.26 | Q9: 49 | R9: 21.75 | S9: 13.03 | T9: =SUM(N9:S9)/M9 -> 0.38084085 | W9: 719.36 | X9: 40.61 | Y9: 38.99 | Z9: 89.55 | AA9: 44.85 | AB9: 22.59 | AC9: 12.5 | AD9: =SUM(X9:AC9)/W9 -> 0.34626613 | AF9: 615.92 | AG9: 23.7 | AH9: 35.79 | AI9: 76.15 | AJ9: 43.65 | AK9: 19.67 | AL9: 10.45 | AM9: =SUM(AG9:AL9)/AF9 -> 0.33999545 | AO9: 585.84 | AP9: 29.97 | AQ9: 37.07 | AR9: 78.76 | AS9: 45.14 | AT9: 17.26 | AU9: 13.72 | AV9: =SUM(AP9:AU9)/AO9 -> 0.3788065 | AX9: 606 | AY9: 33.71 | AZ9: 49.65 | BA9: 82.84 | BB9: 48.64 | BC9: 15.11 | BD9: 14.05 | BE9: =SUM(AY9:BD9)/AX9 -> 0.40264026 | BG9: 558.27 | BH9: 28.34 | BI9: 51.57 | BJ9: 76.79 | BK9: 51.7 | BL9: 16.74 | BM9: 11.81 | BN9: =SUM(BH9:BM9)/BG9 -> 0.4244362
A10: 内蒙古 | B10: 446.87 | C10: 57.37 | D10: 13.78 | E10: 149.07 | F10: 36.55 | G10: 37.2 | H10: 12.15 | I10: =SUM(C10:H10)/B10 -> 0.68503144 | L10: 内蒙古 | M10: 445.36 | N10: 63.44 | O10: 11.44 | P10: 151.27 | Q10: 28.77 | R10: 35.26 | S10: 11.25 | T10: =SUM(N10:S10)/M10 -> 0.67682324 | W10: 445.25 | X10: 65.03 | Y10: 11.19 | Z10: 145.37 | AA10: 34.11 | AB10: 34.05 | AC10: 8.67 | AD10: =SUM(X10:AC10)/W10 -> 0.67023021 | AF10: 391.49 | AG10: 60.95 | AH10: 16.09 | AI10: 120.45 | AJ10: 38.51 | AK10: 23.52 | AL10: 12.03 | AM10: =SUM(AG10:AL10)/AF10 -> 0.69363202 | AO10: 419.88 | AP10: 56.07 | AQ10: 19.47 | AR10: 132.32 | AS10: 46.94 | AT10: 25.19 | AU10: 12.36 | AV10: =SUM(AP10:AU10)/AO10 -> 0.69627036 | AX10: 465.97 | AY10: 67.71 | AZ10: 37.03 | BA10: 136.95 | BB10: 44.67 | BC10: 24.39 | BD10: 12.33 | BE10: =SUM(AY10:BD10)/AX10 -> 0.69334936 | BG10: 399.21 | BH10: 44.92 | BI10: 13.55 | BJ10: 124.32 | BK10: 38.47 | BL10: 25.36 | BM10: 12.78 | BN10: =SUM(BH10:BM10)/BG10 -> 0.64978332
A11: 辽 宁 | B11: 403.19 | C11: 31.67 | D11: 43.65 | E11: 70.09 | F11: 56.18 | G11: 17.96 | H11: 14.99 | I11: =SUM(C11:H11)/B11 -> 0.58171086 | L11: 辽 宁 | M11: 447.51 | N11: 30.68 | O11: 38.06 | P11: 69.84 | Q11: 90.66 | R11: 15.71 | S11: 18.75 | T11: =SUM(N11:S11)/M11 -> 0.58926058 | W11: 466.98 | X11: 35.76 | Y11: 34.32 | Z11: 68.1 | AA11: 103.34 | AB11: 13.8 | AC11: 19.17 | AD11: =SUM(X11:AC11)/W11 -> 0.58779819 | AF11: 448.91 | AG11: 36.65 | AH11: 35.83 | AI11: 61.79 | AJ11: 81.09 | AK11: 13.86 | AL11: 14.75 | AM11: =SUM(AG11:AL11)/AF11 -> 0.54347197 | AO11: 499.97 | AP11: 38.69 | AQ11: 36.84 | AR11: 60.44 | AS11: 104.24 | AT11: 16.35 | AU11: 18.8 | AV11: =SUM(AP11:AU11)/AO11 -> 0.55075305 | AX11: 527.05 | AY11: 41.9 | AZ11: 45.21 | BA11: 60.87 | BB11: 106.02 | BC11: 14.36 | BD11: 21.55 | BE11: =SUM(AY11:BD11)/AX11 -> 0.55006166 | BG11: 484.29 | BH11: 36.15 | BI11: 35.53 | BJ11: 55.9 | BK11: 92.83 | BL11: 16.02 | BM11: 22.93 | BN11: =SUM(BH11:BM11)/BG11 -> 0.53554688
A12: 吉 林 | B12: 130.64 | C12: 4.03 | D12: 0.98 | E12: 34.74 | F12: 3.88 | G12: 7.79 | H12: 7.86 | I12: =SUM(C12:H12)/B12 -> 0.45376607 | L12: 吉 林 | M12: 147.71 | N12: 7.72 | O12: 0.95 | P12: 35.75 | Q12: 9.3 | R12: 1.11 | S12: 7.54 | T12: =SUM(N12:S12)/M12 -> 0.42224629 | W12: 154.39 | X12: 10.24 | Y12: 0.77 | Z12: 35.34 | AA12: 13.86 | AB12: 16.45 | AC12: 8.2 | AD12: =SUM(X12:AC12)/W12 -> 0.549647 | AF12: 207.9 | AG12: 9.61 | AH12: 1.03 | AI12: 34.72 | AJ12: 6.53 | AK12: 23.99 | AL12: 21.78 | AM12: =SUM(AG12:AL12)/AF12 -> 0.46974507 | AO12: 232.62 | AP12: 11.14 | AQ12: 1.11 | AR12: 39.8 | AS12: 5.17 | AT12: 26.93 | AU12: 26.51 | AV12: =SUM(AP12:AU12)/AO12 -> 0.47571146 | AX12: 235.11 | AY12: 14.97 | AZ12: 1.33 | BA12: 43.61 | BB12: 5.71 | BC12: 18.58 | BD12: 28.88 | BE12: =SUM(AY12:BD12)/AX12 -> 0.48096636 | BG12: 209.83 | BH12: 10.92 | BI12: 1.3 | BJ12: 43.74 | BK12: 4.42 | BL12: 9.91 | BM12: 23.44 | BN12: =SUM(BH12:BM12)/BG12 -> 0.44669494
A13: 黑龙江 | B13: 162.29 | C13: 5.03 | D13: 7.99 | E13: 40.82 | F13: 4.86 | G13: 2.11 | H13: 3.99 | I13: =SUM(C13:H13)/B13 -> 0.39928523 | L13: 黑龙江 | M13: 155.94 | N13: 4.58 | O13: 5.71 | P13: 35.98 | Q13: 3.78 | R13: 1.64 | S13: 3.01 | T13: =SUM(N13:S13)/M13 -> 0.35077594 | W13: 130.02 | X13: 7.61 | Y13: 5.89 | Z13: 39.79 | AA13: 3.99 | AB13: 1.5 | AC13: 4.37 | AD13: =SUM(X13:AC13)/W13 -> 0.48569451 | AF13: 130.12 | AG13: 5.27 | AH13: 6.82 | AI13: 34.55 | AJ13: 6.41 | AK13: 2.1 | AL13: 4.61 | AM13: =SUM(AG13:AL13)/AF13 -> 0.45926837 | AO13: 150.92 | AP13: 5.63 | AQ13: 9.37 | AR13: 40.68 | AS13: 5.53 | AT13: 1.34 | AU13: 5.75 | AV13: =SUM(AP13:AU13)/AO13 -> 0.45255765 | AX13: 181.14 | AY13: 5.06 | AZ13: 13.56 | BA13: 46.68 | BB13: 7.49 | BC13: 1.15 | BD13: 7.97 | BE13: =SUM(AY13:BD13)/AX13 -> 0.45219167 | BG13: 169.3 | BH13: 4.29 | BI13: 13.81 | BJ13: 42.54 | BK13: 10.7 | BL13: 0.95 | BM13: 7.37 | BN13: =SUM(BH13:BM13)/BG13 -> 0.47052569
A14: 上 海 | B14: 175.19 | C14: 12.17 | D14: 4.61 | E14: 16.8 | F14: 18.46 | G14: 2.44 | H14: 2.92 | I14: =SUM(C14:H14)/B14 -> 0.32764427 | L14: 上 海 | M14: 198.55 | N14: 13.37 | O14: 4.18 | P14: 19.18 | Q14: 23.45 | R14: 3.14 | S14: 2.92 | T14: =SUM(N14:S14)/M14 -> 0.33361874 | W14: 196.63 | X14: 14.92 | Y14: 1.05 | Z14: 18.29 | AA14: 24.11 | AB14: 3.36 | AC14: 2.75 | AD14: =SUM(X14:AC14)/W14 -> 0.32792555 | AF14: 188.12 | AG14: 17.17 | AH14: 1.1 | AI14: 15.34 | AJ14: 22.24 | AK14: 3.85 | AL14: 2.69 | AM14: =SUM(AG14:AL14)/AF14 -> 0.33165001 | AO14: 213.89 | AP14: 20.99 | AQ14: 3.99 | AR14: 16.75 | AS14: 14.38 | AT14: 4.88 | AU14: 4.09 | AV14: =SUM(AP14:AU14)/AO14 -> 0.30426855 | AX14: 261.05 | AY14: 22.71 | AZ14: 6.23 | BA14: 17.55 | BB14: 16.82 | BC14: 5.05 | BD14: 5.91 | BE14: =SUM(AY14:BD14)/AX14 -> 0.28450488 | BG14: 218.81 | BH14: 21.48 | BI14: 6.82 | BJ14: 18.03 | BK14: 16.08 | BL14: 5 | BM14: 6.2 | BN14: =SUM(BH14:BM14)/BG14 -> 0.33641058
A15: 江 苏 | B15: 696.69 | C15: 51.97 | D15: 7.24 | E15: 85.56 | F15: 49.3 | G15: 17.03 | H15: 24.61 | I15: =SUM(C15:H15)/B15 -> 0.33832838 | L15: 江 苏 | M15: 1022.14 | N15: 91.03 | O15: 6.62 | P15: 119.94 | Q15: 60.44 | R15: 29.37 | S15: 35.76 | T15: =SUM(N15:S15)/M15 -> 0.335727 | W15: 1110.39 | X15: 115.84 | Y15: 12.53 | Z15: 110.18 | AA15: 72.06 | AB15: 28.83 | AC15: 34.89 | AD15: =SUM(X15:AC15)/W15 -> 0.33711579 | AF15: 1172.75 | AG15: 153.76 | AH15: 8.86 | AI15: 80.28 | AJ15: 98.39 | AK15: 29.94 | AL15: 43.78 | AM15: =SUM(AG15:AL15)/AF15 -> 0.35387764 | AO15: 1280.55 | AP15: 165.93 | AQ15: 11.53 | AR15: 83.54 | AS15: 109.19 | AT15: 33.42 | AU15: 46.02 | AV15: =SUM(AP15:AU15)/AO15 -> 0.35112256 | AX15: 1350.63 | AY15: 175.4 | AZ15: 12.71 | BA15: 102.02 | BB15: 125.59 | BC15: 30.81 | BD15: 53.59 | BE15: =SUM(AY15:BD15)/AX15 -> 0.37028646 | BG15: 1297.51 | BH15: 159.05 | BI15: 8.38 | BJ15: 109.32 | BK15: 135.91 | BL15: 29.64 | BM15: 52.14 | BN15: =SUM(BH15:BM15)/BG15 -> 0.38106835
A16: 浙 江 | B16: 843.99 | C16: 55.4 | D16: 31.75 | E16: 104.29 | F16: 13 | G16: 16.7 | H16: 33.86 | I16: =SUM(C16:H16)/B16 -> 0.30213628 | L16: 浙 江 | M16: 863.99 | N16: 61.22 | O16: 7.25 | P16: 114.25 | Q16: 12.3 | R16: 20.49 | S16: 34.2 | T16: =SUM(N16:S16)/M16 -> 0.28901955 | W16: 850.04 | X16: 67.89 | Y16: 7.22 | Z16: 102.15 | AA16: 18.77 | AB16: 24.82 | AC16: 33.62 | AD16: =SUM(X16:AC16)/W16 -> 0.29936238 | AF16: 895.56 | AG16: 78.75 | AH16: 5.78 | AI16: 101.17 | AJ16: 22.42 | AK16: 27.54 | AL16: 35.39 | AM16: =SUM(AG16:AL16)/AF16 -> 0.30265979 | AO16: 1054.35 | AP16: 89.08 | AQ16: 3.69 | AR16: 113.34 | AS16: 28.36 | AT16: 33.66 | AU16: 44.47 | AV16: =SUM(AP16:AU16)/AO16 -> 0.29648599 | AX16: 1156.97 | AY16: 96.67 | AZ16: 3.28 | BA16: 112.12 | BB16: 42.78 | BC16: 35.31 | BD16: 48.06 | BE16: =SUM(AY16:BD16)/AX16 -> 0.29233256 | BG16: 1137.49 | BH16: 90.17 | BI16: 5.41 | BJ16: 90.35 | BK16: 46.38 | BL16: 35.65 | BM16: 47.36 | BN16: =SUM(BH16:BM16)/BG16 -> 0.27720683
... A25: 广 西 | B25: 220.61 | C25: 4.43 | D25: 1.51 | E25: 77.03 | F25: 19.27 | G25: 26.06 | H25: 9.22 | I25: =SUM(C25:H25)/B25 -> 0.62336249 | L25: 广 西 | M25: 210.86 | N25: 5.15 | O25: 2.08 | P25: 66.19 | Q25: 14.96 | R25: 24.5 | S25: 10.11 | T25: =SUM(N25:S25)/M25 -> 0.583278 | W25: 206.78 | X25: 7.32 | Y25: 2.84 | Z25: 61.94 | AA25: 16.65 | AB25: 17.09 | AC25: 9.62 | AD25: =SUM(X25:AC25)/W25 -> 0.55837122 | AF25: 218.95 | AG25: 8.88 | AH25: 2.07 | AI25: 58.08 | AJ25: 19.34 | AK25: 19.43 | AL25: 11.91 | AM25: =SUM(AG25:AL25)/AF25 -> 0.54674583 | AO25: 228.56 | AP25: 10.59 | AQ25: 2.64 | AR25: 56.1 | AS25: 21.48 | AT25: 23.54 | AU25: 12.36 | AV25: =SUM(AP25:AU25)/AO25 -> 0.55438397 | AX25: 239.25 | AY25: 10.57 | AZ25: 2.92 | BA25: 61.7 | BB25: 22.49 | BC25: 23.76 | BD25: 11.43 | BE25: =SUM(AY25:BD25)/AX25 -> 0.5553605 | BG25: 224.07 | BH25: 11.04 | BI25: 2.91 | BJ25: 62.34 | BK25: 21.6 | BL25: 19.71 | BM25: 10.63 | BN25: =SUM(BH25:BM25)/BG25 -> 0.57227652
A26: 海 南 | B26: 40.57 | C26: 2.62 | D26: 2.3 | E26: 17.89 | G26: 0.02 | H26: 2.23 | I26: =SUM(C26:H26)/B26 -> 0.61769781 | L26: 海 南 | M26: 45.14 | N26: 3.43 | O26: 2.61 | P26: 18.88 | R26: 0.01 | S26: 2.07 | T26: =SUM(N26:S26)/M26 -> 0.59813912 | W26: 45.39 | X26: 4 | Y26: 2.32 | Z26: 18.15 | AB26: 0.02 | AC26: 2.75 | AD26: =SUM(X26:AC26)/W26 -> 0.60013219 | AF26: 38.53 | AG26: 3.57 | AH26: 2.15 | AI26: 14.74 | AJ26: 0.34 | AL26: 2.3 | AM26: =SUM(AG26:AL26)/AF26 -> 0.59953283 | AO26: 33 | AP26: 4.68 | AQ26: 1.64 | AR26: 8.01 | AS26: 0.36 | AT26: 0.01 | AU26: 2.27 | AV26: =SUM(AP26:AU26)/AO26 -> 0.51424242 | AX26: 25.45 | AY26: 0.54 | AZ26: 0.77 | BA26: 4.47 | BB26: 0.04 | BC26: 0.02 | BD26: 2.44 | BE26: =SUM(AY26:BD26)/AX26 -> 0.32534381 | BG26: 26.69 | BH26: 0.34 | BI26: 0.67 | BJ26: 9.64 | BL26: 0.01 | BM26: 2.38 | BN26: =SUM(BH26:BM26)/BG26 -> 0.4885725
A27: 重 庆 | B27: 166.83 | C27: 7.91 | D27: 0.29 | E27: 35.24 | F27: 4.61 | G27: 6.82 | H27: 15.34 | I27: =SUM(C27:H27)/B27 -> 0.42084757 | L27: 重 庆 | M27: 193.85 | N27: 13.42 | O27: 0.43 | P27: 38.25 | Q27: 4.35 | R27: 9 | S27: 17.61 | T27: =SUM(N27:S27)/M27 -> 0.42847563 | W27: 199.87 | X27: 16.35 | Y27: 0.67 | Z27: 37.11 | AA27: 4.34 | AB27: 8.68 | AC27: 16.09 | AD27: =SUM(X27:AC27)/W27 -> 0.41647071 | AF27: 226.82 | AG27: 20.91 | AH27: 0.44 | AI27: 34.73 | AJ27: 15.78 | AK27: 11 | AL27: 17.14 | AM27: =SUM(AG27:AL27)/AF27 -> 0.44087823 | AO27: 218.8 | AP27: 20.43 | AQ27: 0.47 | AR27: 42.2 | AS27: 8.25 | AT27: 11.66 | AU27: 20.15 | AV27: =SUM(AP27:AU27)/AO27 -> 0.4714808 | AX27: 226.06 | AY27: 16.61 | AZ27: 0.45 | BA27: 42.6 | BB27: 19.35 | BC27: 13.62 | BD27: 19.47 | BE27: =SUM(AY27:BD27)/AX27 -> 0.49588605 | BG27: 199.76 | BH27: 18.17 | BI27: 0.4 | BJ27: 36.57 | BK27: 14.82 | BL27: 10.93 | BM27: 16.69 | BN27: =SUM(BH27:BM27)/BG27 -> 0.48848618
A28: 四 川 | B28: 547.6 | C28: 22.13 | D28: 3.02 | E28: 198.5 | F28: 37.21 | G28: 6.25 | H28: 31.6 | I28: =SUM(C28:H28)/B28 -> 0.54548941 | L28: 四 川 | M28: 604.18 | N28: 25.09 | O28: 3.05 | P28: 211.39 | Q28: 45.58 | R28: 5.95 | S28: 34.31 | T28: =SUM(N28:S28)/M28 -> 0.53853156 | W28: 589.2 | X28: 26.52 | Y28: 3.38 | Z28: 203.78 | AA28: 41.64 | AB28: 6.68 | AC28: 34.35 | AD28: =SUM(X28:AC28)/W28 -> 0.53691446 | AF28: 607.19 | AG28: 43.07 | AH28: 7.28 | AI28: 197.99 | AJ28: 44.39 | AK28: 6.14 | AL28: 37.27 | AM28: =SUM(AG28:AL28)/AF28 -> 0.55359937 | AO28: 653.8 | AP28: 40.53 | AQ28: 11.02 | AR28: 223.28 | AS28: 38.83 | AT28: 7.69 | AU28: 37.64 | AV28: =SUM(AP28:AU28)/AO28 -> 0.54908229 | AX28: 706.72 | AY28: 40.96 | AZ28: 12.77 | BA28: 232.32 | BB28: 67.96 | BC28: 9.99 | BD28: 55.08 | BE28: =SUM(AY28:BD28)/AX28 -> 0.59299298 | BG28: 574.86 | BH28: 42.49 | BI28: 2.79 | BJ28: 150.05 | BK28: 54.88 | BL28: 10.5 | BM28: 34.25 | BN28: =SUM(BH28:BM28)/BG28 -> 0.51309884
A29: 贵 州 | B29: 191.46 | C29: 16.54 | D29: 2.16 | E29: 98.06 | F29: 4.32 | G29: 7.3 | H29: 10.34 | I29: =SUM(C29:H29)/B29 -> 0.72453776 | L29: 贵 州 | M29: 195.34 | N29: 23.36 | O29: 2.49 | P29: 88.4 | Q29: 3.87 | R29: 8.1 | S29: 12.95 | T29: =SUM(N29:S29)/M29 -> 0.71245009 | W29: 196.37 | X29: 25.75 | Y29: 2.7 | Z29: 84.41 | AA29: 4.17 | AB29: 8.17 | AC29: 13.64 | AD29: =SUM(X29:AC29)/W29 -> 0.70703264 | AF29: 209.74 | AG29: 30.53 | AH29: 2.75 | AI29: 84.01 | AJ29: 2.91 | AK29: 8.67 | AL29: 14.91 | AM29: =SUM(AG29:AL29)/AF29 -> 0.6855154 | AO29: 238.26 | AP29: 35.37 | AQ29: 2.43 | AR29: 100.02 | AS29: 3.34 | AT29: 11.4 | AU29: 16.41 | AV29: =SUM(AP29:AU29)/AO29 -> 0.70918325 | AX29: 224.14 | AY29: 25.19 | AZ29: 1.44 | BA29: 99.44 | BB29: 5.81 | BC29: 9.99 | BD29: 14.3 | BE29: =SUM(AY29:BD29)/AX29 -> 0.69675203 | BG29: 197.02 | BH29: 23.43 | BI29: 1.51 | BJ29: 89.95 | BK29: 6.02 | BL29: 7.08 | BM29: 11.58 | BN29: =SUM(BH29:BM29)/BG29 -> 0.70840524
A30: 云 南 | B30: 299.46 | C30: 13.46 | D30: 2.88 | E30: 181.11 | F30: 8.02 | G30: 25.63 | H30: 7.8 | I30: =SUM(C30:H30)/B30 -> 0.79776932 | L30: 云 南 | M30: 332.17 | N30: 16.17 | O30: 5.37 | P30: 189.31 | Q30: 10.49 | R30: 32.25 | S30: 9.86 | T30: =SUM(N30:S30)/M30 -> 0.79311798 | W30: 305.28 | X30: 19.92 | Y30: 6.06 | Z30: 151.6 | AA30: 11 | AB30: 38.95 | AC30: 11.48 | AD30: =SUM(X30:AC30)/W30 -> 0.7829206 | AF30: 321.48 | AG30: 24.47 | AH30: 6.9 | AI30: 151.64 | AJ30: 13.81 | AK30: 52.37 | AL30: 9.35 | AM30: =SUM(AG30:AL30)/AF30 -> 0.80421799 | AO30: 366.09 | AP30: 31.75 | AQ30: 7.83 | AR30: 173.85 | AS30: 17.35 | AT30: 54.86 | AU30: 13.63 | AV30: =SUM(AP30:AU30)/AO30 -> 0.81747658 | AX30: 356.79 | AY30: 29.61 | AZ30: 7.58 | BA30: 163.79 | BB30: 17.78 | BC30: 52.87 | BD30: 13.52 | BE30: =SUM(AY30:BD30)/AX30 -> 0.79920962 | BG30: 292.54 | BH30: 25.56 | BI30: 7.89 | BJ30: 128.15 | BK30: 15.73 | BL30: 41.63 | BM30: 10.75 | BN30: =SUM(BH30:BM30)/BG30 -> 0.78522595
A31: 西 藏 | B31: 10.58 | C31: 0.06 | E31: 5.08 | H31: 0.84 | I31: =SUM(C31:H31)/B31 -> 0.56521739 | L31: 西 藏 | M31: 10 | N31: 0.03 | P31: 4.84 | S31: 0.45 | T31: =SUM(N31:S31)/M31 -> 0.532 | W31: 8.06 | X31: 0.05 | Z31: 4.32 | AC31: 0.51 | AD31: =SUM(X31:AC31)/W31 -> 0.60545906 | AF31: 4.98 | AG31: 0.03 | AI31: 3.66 | AL31: 0.31 | AM31: =SUM(AG31:AL31)/AF31 -> 0.80321285 | AO31: 5.61 | AP31: 0.03 | AR31: 4.26 | AU31: 0.25 | AV31: =SUM(AP31:AU31)/AO31 -> 0.80926916 | AX31: 2.91 | AY31: 0.02 | BA31: 1.44 | BD31: 0.13 | BE31: =SUM(AY31:BD31)/AX31 -> 0.54639175 | BG31: 2.56 | BH31: 0.01 | BJ31: 1.07 | BM31: 0.19 | BN31: =SUM(BH31:BM31)/BG31 -> 0.49609375
A32: 陕 西 | B32: 307.67 | C32: 35.68 | D32: 42.19 | E32: 62.82 | F32: 7.26 | G32: 15.76 | H32: 10.58 | I32: =SUM(C32:H32)/B32 -> 0.56648357 | L32: 陕 西 | M32: 373.81 | N32: 35.66 | O32: 67.42 | P32: 54.97 | Q32: 9.68 | R32: 14.59 | S32: 11.99 | T32: =SUM(N32:S32)/M32 -> 0.51980953 | W32: 348.32 | X32: 39.83 | Y32: 65.27 | Z32: 44.65 | AA32: 10.04 | AB32: 14.38 | AC32: 11.81 | AD32: =SUM(X32:AC32)/W32 -> 0.53393431 | AF32: 325.67 | AG32: 42.41 | AH32: 37.31 | AI32: 49.59 | AJ32: 10.42 | AK32: 20.53 | AL32: 9.83 | AM32: =SUM(AG32:AL32)/AF32 -> 0.52227715 | AO32: 315.94 | AP32: 34.46 | AQ32: 24.11 | AR32: 51.96 | AS32: 10.76 | AT32: 21.4 | AU32: 10.14 | AV32: =SUM(AP32:AU32)/AO32 -> 0.48373109 | AX32: 327.21 | AY32: 24.46 | AZ32: 41.54 | BA32: 55.14 | BB32: 7.51 | BC32: 21.88 | BD32: 13.42 | BE32: =SUM(AY32:BD32)/AX32 -> 0.50105437 | BG32: 291.92 | BH32: 19.47 | BI32: 34.7 | BJ32: 58.03 | BK32: 7.87 | BL32: 17.27 | BM32: 9.66 | BN32: =SUM(BH32:BM32)/BG32 -> 0.50356262
A33: 甘 肃 | B33: 158.84 | C33: 2.81 | D33: 5.83 | E33: 68.35 | F33: 7.64 | G33: 30.85 | H33: 5.66 | I33: =SUM(C33:H33)/B33 -> 0.76265424 | L33: 甘 肃 | M33: 193.49 | N33: 3.94 | O33: 5.07 | P33: 69.43 | Q33: 27.69 | R33: 34.01 | S33: 6.48 | T33: =SUM(N33:S33)/M33 -> 0.75776526 | W33: 215.28 | X33: 5.1 | Y33: 4.96 | Z33: 78.02 | AA33: 29.97 | AB33: 43.97 | AC33: 7.29 | AD33: =SUM(X33:AC33)/W33 -> 0.78646414 | AF33: 202.46 | AG33: 4.2 | AH33: 8.26 | AI33: 68.59 | AJ33: 29.54 | AK33: 40.72 | AL33: 7.48 | AM33: =SUM(AG33:AL33)/AF33 -> 0.78430307 | AO33: 236.92 | AP33: 3.78 | AQ33: 26.98 | AR33: 73.63 | AS33: 37.78 | AT33: 44.41 | AU33: 7.1 | AV33: =SUM(AP33:AU33)/AO33 -> 0.81749114 | AX33: 219.55 | AY33: 4.84 | AZ33: 13.79 | BA33: 69.55 | BB33: 38.36 | BC33: 40.07 | BD33: 7.74 | BE33: =SUM(AY33:BD33)/AX33 -> 0.79412435 | BG33: 190.58 | BH33: 4.46 | BI33: 13.01 | BJ33: 57.67 | BK33: 27.63 | BL33: 42.94 | BM33: 7.87 | BN33: =SUM(BH33:BM33)/BG33 -> 0.80585581
A34: 青 海 | B34: 88.83 | C34: 11.87 | D34: 0.41 | E34: 45.33 | F34: 3.37 | G34: 10.75 | H34: 0.94 | I34: =SUM(C34:H34)/B34 -> 0.81807948 | L34: 青 海 | M34: 114.75 | N34: 12.1 | O34: 0.41 | P34: 49.4 | Q34: 7.55 | R34: 24.66 | S34: 4.37 | T34: =SUM(N34:S34)/M34 -> 0.85830065 | W34: 105.85 | X34: 12.49 | Y34: 0.61 | Z34: 38.5 | AA34: 13.49 | AB34: 20.4 | AC34: 5.48 | AD34: =SUM(X34:AC34)/W34 -> 0.85942371 | AF34: 101.22 | AG34: 23.21 | AH34: 0.19 | AI34: 46.73 | AJ34: 4.33 | AK34: 12.16 | AL34: 5.09 | AM34: =SUM(AG34:AL34)/AF34 -> 0.90604624 | AO34: 100.91 | AP34: 21.78 | AQ34: 0.27 | AR34: 46.54 | AS34: 6.61 | AT34: 12.76 | AU34: 3.26 | AV34: =SUM(AP34:AU34)/AO34 -> 0.90397384 | AX34: 108.54 | AY34: 20.06 | AZ34: 1.15 | BA34: 45.21 | BB34: 8.43 | BC34: 16.27 | BD34: 3.8 | BE34: =SUM(AY34:BD34)/AX34 -> 0.87451631 | BG34: 91.02 | BH34: 17.5 | BI34: 1.23 | BJ34: 36.55 | BK34: 6.2 | BL34: 14.83 | BM34: 2.81 | BN34: =SUM(BH34:BM34)/BG34 -> 0.8692595
A35: 宁 夏 | B35: 162.11 | C35: 16.3 | D35: 3.23 | E35: 69.02 | F35: 23.31 | G35: 4.68 | H35: 2.15 | I35: =SUM(C35:H35)/B35 -> 0.73215718 | L35: 宁 夏 | M35: 156.64 | N35: 15.7 | O35: 6.66 | P35: 63.33 | Q35: 20.58 | R35: 5.23 | S35: 2.21 | T35: =SUM(N35:S35)/M35 -> 0.72593207 | W35: 162.92 | X35: 17.56 | Y35: 19.15 | Z35: 58.88 | AA35: 14.49 | AB35: 6.56 | AC35: 2.36 | AD35: =SUM(X35:AC35)/W35 -> 0.73041984 | AF35: 128.01 | AG35: 16.42 | AH35: 12.72 | AI35: 44.41 | AJ35: 4.94 | AK35: 6.86 | AL35: 2.44 | AM35: =SUM(AG35:AL35)/AF35 -> 0.6858058 | AO35: 134.25 | AP35: 9.09 | AQ35: 10.84 | AR35: 41.52 | AS35: 5.88 | AT35: 11.11 | AU35: 3.32 | AV35: =SUM(AP35:AU35)/AO35 -> 0.60901304 | AX35: 129.39 | AY35: 9.88 | AZ35: 7.12 | BA35: 45.12 | BB35: 5.16 | BC35: 12.06 | BD35: 3.36 | BE35: =SUM(AY35:BD35)/AX35 -> 0.63915295 | BG35: 105.43 | BH35: 5.82 | BI35: 6.88 | BJ35: 37.04 | BK35: 4.33 | BL35: 12.54 | BM35: 3.35 | BN35: =SUM(BH35:BM35)/BG35 -> 0.66356824
A36: 新 疆 | B36: 289.72 | C36: 30.18 | D36: 9.31 | E36: 118.06 | F36: 6.76 | G36: 25.17 | H36: 13.31 | I36: =SUM(C36:H36)/B36 -> 0.69995168 | L36: 新 疆 | M36: 315.23 | O36: 10.07 | P36: 7.75 | Q36: 26.9 | R36: 18.35 | T36: =SUM(N36:S36)/M36 -> 0.20007613 | W36: 292.17 | X36: 33.66 | Y36: 11.63 | Z36: 110.39 | AA36: 9.51 | AB36: 32.38 | AC36: 15.56 | AD36: =SUM(X36:AC36)/W36 -> 0.72947257 | AF36: 293.61 | AG36: 38.04 | AH36: 7.02 | AI36: 86.27 | AJ36: 22.24 | AK36: 26.93 | AL36: 16.87 | AM36: =SUM(AG36:AL36)/AF36 -> 0.67221825 | AO36: 298.64 | AP36: 42.49 | AQ36: 8 | AR36: 83.88 | AS36: 23.42 | AT36: 24.55 | AU36: 18.33 | AV36: =SUM(AP36:AU36)/AO36 -> 0.67194616 | AX36: 278.7 | AY36: 38.15 | AZ36: 11.59 | BA36: 65.31 | BB36: 23.78 | BC36: 16.01 | BD36: 20.48 | BE36: =SUM(AY36:BD36)/AX36 -> 0.62906351 | BG36: 210.35 | BH36: 28.52 | BI36: 12.29 | BJ36: 44.32 | BK36: 17.08 | BL36: 9.13 | BM36: 16.35 | BN36: =SUM(BH36:BM36)/BG36 -> 0.60703589
B39: 更多数据：关注公众号【马克数据网】

Sheet 2017年插值法填充
A1: 2017年插值法填充
B2: 总 | C2: 化学 | D2: 石油 | E2: 电力热力 | F2: 黑色金属 | G2: 有色金属 | H2: 非金属
A3: 全 国 | B3: 12404.31 | C3: 1001.65 | D3: 378.34 | E3: 2159.47 | F3: 895.23 | G3: 663.94 | H3: 568.14 | I3: =SUM(C3:H3)/B3 -> 0.45683879
A4: 北 京 | B4: 259.6 | C4: 3.87 | D4: 1.67 | E4: 51.04 | F4: 1.45 | G4: 0.43 | H4: 16.18 | I4: =SUM(C4:H4)/B4 -> 0.28751926
A5: 天 津 | B5: 311.97 | C5: 17.55 | D5: 3.05 | E5: 15.13 | F5: 51.91 | G5: 5.4 | H5: 3.12 | I5: =SUM(C5:H5)/B5 -> 0.30823477
A6: 河 北 | B6: 537.11 | C6: 25.98 | D6: 17.91 | E6: 62.8 | F6: 145.83 | G6: 6.03 | H6: 29.93 | I6: =SUM(C6:H6)/B6 -> 0.53709668
A7: 山 西 | B7: 667.64 | C7: 32.16 | D7: 37.39 | E7: 82.85 | F7: 44.25 | G7: 21.13 | H7: 11.48 | I7: =SUM(C7:H7)/B7 -> 0.34338865
A8: 内蒙古 | B8: 418.37 | C8: 62.99 | D8: 13.64 | E8: 132.91 | F8: 36.31 | G8: 28.78 | H8: 10.35 | I8: =SUM(C8:H8)/B8 -> 0.68116739
A9: 辽 宁 | B9: 457.95 | C9: 36.21 | D9: 35.08 | E9: 64.95 | F9: 92.22 | G9: 13.83 | H9: 16.96 | I9: =SUM(C9:H9)/B9 -> 0.56610984
A10: 吉 林 | B10: 181.14 | C10: 9.93 | D10: 0.9 | E10: 35.03 | F10: 10.2 | G10: 20.22 | H10: 14.99 | I10: =SUM(C10:H10)/B10 -> 0.50386441
A11: 黑龙江 | B11: 130.07 | C11: 6.44 | D11: 6.36 | E11: 37.17 | F11: 5.2 | G11: 1.8 | H11: 4.49 | I11: =SUM(C11:H11)/B11 -> 0.4725148
A12: 上 海 | B12: 192.38 | C12: 16.05 | D12: 1.08 | E12: 16.81 | F12: 23.17 | G12: 3.61 | H12: 2.72 | I12: =SUM(C12:H12)/B12 -> 0.32976401
A13: 江 苏 | B13: 1141.57 | C13: 134.8 | D13: 10.7 | E13: 95.23 | F13: 85.23 | G13: 29.38 | H13: 39.34 | I13: =SUM(C13:H13)/B13 -> 0.34573438
A14: 浙 江 | B14: 872.8 | C14: 73.32 | D14: 6.5 | E14: 101.66 | F14: 20.6 | G14: 26.18 | H14: 34.5 | I14: =SUM(C14:H14)/B14 -> 0.30105408
... A23: 广 西 | B23: 212.87 | C23: 8.1 | D23: 2.46 | E23: 60.01 | F23: 17.99 | G23: 18.26 | H23: 10.77 | I23: =SUM(C23:H23)/B23 -> 0.55240287
A24: 海 南 | B24: 41.96 | C24: 3.79 | D24: 2.24 | E24: 16.45 | H24: 2.53 | I24: =SUM(C24:H24)/B24 -> 0.59604385
A25: 重 庆 | B25: 213.35 | C25: 18.63 | D25: 0.56 | E25: 35.92 | F25: 10.06 | G25: 9.84 | H25: 16.62 | I25: =SUM(C25:H25)/B25 -> 0.42948207
A26: 四 川 | B26: 598.2 | C26: 34.8 | D26: 5.33 | E26: 200.89 | F26: 43.02 | G26: 6.41 | H26: 35.81 | I26: =SUM(C26:H26)/B26 -> 0.54540288
A27: 贵 州 | B27: 203.06 | C27: 28.14 | D27: 2.73 | E27: 84.21 | F27: 3.54 | G27: 8.42 | H27: 14.28 | I27: =SUM(C27:H27)/B27 -> 0.69595194
A28: 云 南 | B28: 313.38 | C28: 22.2 | D28: 6.48 | E28: 151.62 | F28: 12.41 | G28: 45.66 | H28: 10.42 | I28: =SUM(C28:H28)/B28 -> 0.7938924
A29: 西 藏 | B29: 6.52 | C29: 0.04 | E29: 3.99 | H29: 0.41 | I29: =SUM(C29:H29)/B29 -> 0.6809816
A30: 陕 西 | B30: 337 | C30: 41.12 | D30: 51.29 | E30: 47.12 | F30: 10.23 | G30: 17.46 | H30: 10.82 | I30: =SUM(C30:H30)/B30 -> 0.52830861
A31: 甘 肃 | B31: 208.87 | C31: 4.65 | D31: 6.61 | E31: 73.31 | F31: 29.76 | G31: 42.35 | H31: 7.39 | I31: =SUM(C31:H31)/B31 -> 0.78551252
A32: 青 海 | B32: 103.54 | C32: 17.85 | D32: 0.4 | E32: 42.61 | F32: 8.91 | G32: 16.28 | H32: 5.29 | I32: =SUM(C32:H32)/B32 -> 0.88217114
A33: 宁 夏 | B33: 145.46 | C33: 16.99 | D33: 15.93 | E33: 51.64 | F33: 9.72 | G33: 6.71 | H33: 2.4 | I33: =SUM(C33:H33)/B33 -> 0.7107796
A34: 新 疆 | B34: 292.89 | C34: 35.85 | D34: 9.33 | E34: 98.33 | F34: 15.88 | G34: 29.66 | H34: 16.22 | I34: =SUM(C34:H34)/B34 -> 0.70084332
J36: 更多数据：关注公众号【马克数据网】

Sheet 2006-2013计算过程
B1: 2013中国工业统计年鉴 | K1: 2012中国工业统计年鉴 | T1: 2011中国工业统计年鉴 | AC1: 2010中国工业统计年鉴 | AL1: 2009中国工业统计年鉴 | AV1: 2008中国工业统计年鉴 | BG1: 2007中国工业统计年鉴 | BQ1: 2006中国工业统计年鉴
A2: 地 区 | B2: 总 | C2: 化学 | D2: 石油 | E2: 电力热力 | F2: 黑色金属 | G2: 有色金属 | H2: 非金属 | K2: 总 | L2: 化学 | M2: 石油 | N2: 电力热力 | O2: 黑色金属 | P2: 有色金属 | Q2: 非金属 | T2: 总 | U2: 化学 | V2: 石油 | W2: 电力热力 | X2: 黑色金属 | Y2: 有色金属 | Z2: 非金属 | AC2: 总 | AD2: 化学 | AE2: 石油 | AF2: 电力热力 | AG2: 黑色金属 | AH2: 有色金属 | AI2: 非金属 | AL2: 总 | AM2: 化学 | AN2: 石油 | AO2: 电力热力 | AP2: 黑色金属 | AQ2: 有色金属 | AR2: 非金属 | AV2: 总 | AW2: 化学 | AX2: 石油 | AY2: 电力热力 | AZ2: 黑色金属 | BA2: 有色金属 | BB2: 非金属 | BF2: 地 区 | BG2: 总 | BH2: 化学 | BI2: 石油 | BJ2: 电力热力 | BK2: 黑色金属 | BL2: 有色金属 | BM2: 非金属 | BP2: 地 区 | BQ2: 总 | BR2: 化学 | BS2: 石油 | BT2: 电力热力 | BU2: 黑色金属 | BV2: 有色金属 | BW2: 非金属
B3: 利息支出 | C3: 利息支出 | D3: 利息支出 | E3: 利息支出 | F3: 利息支出 | G3: 利息支出 | H3: 利息支出 | U3: 利息支出 | V3: 利息支出 | W3: 利息支出 | X3: 利息支出 | Y3: 利息支出 | Z3: 利息支出 | BG3: 利息支出 | BH3: 利息支出 | BI3: 利息支出 | BJ3: 利息支出 | BK3: 利息支出 | BL3: 利息支出 | BM3: 利息支出 | BQ3: 利息支出 | BR3: 利息支出 | BS3: 利息支出 | BT3: 利息支出 | BU3: 利息支出 | BV3: 利息支出 | BW3: 利息支出
A4: 全 国 | B4: 11530.63 | C4: 873.31 | D4: 333.47 | E4: 2101.93 | F4: 1110.67 | G4: 561.44 | H4: 543.59 | I4: =SUM(C4:H4)/B4 -> 0.47910739 | K4: 9054.3 | L4: 659.32 | M4: 272.32 | N4: 1714.27 | O4: 891.71 | P4: 448.36 | Q4: 433.7 | R4: =SUM(L4:Q4)/K4 -> 0.4881305 | T4: 6274.2 | U4: 464.12 | V4: 182.04 | W4: 1383.73 | X4: 600.29 | Y4: 297.72 | Z4: 305.75 | AA4: =SUM(U4:Z4)/T4 -> 0.51538842 | AC4: 5323.01 | AD4: 383.02 | AE4: 149.05 | AF4: 1278.03 | AG4: 474.34 | AH4: 216.47 | AI4: 246.62 | AJ4: =SUM(AD4:AI4)/AC4 -> 0.51616097 | AL4: 5664.16 | AM4: 390.11 | AN4: 195.79 | AO4: 1277.94 | AP4: 570.61 | AQ4: 226.96 | AR4: 252.86 | AS4: =SUM(AM4:AR4)/AL4 -> 0.51451054 | AV4: 4163.31 | AW4: 295.02 | AX4: 119.79 | AY4: 945.09 | AZ4: 397.34 | BA4: 161.72 | BB4: 191.75 | BC4: =SUM(AW4:BB4)/AV4 -> 0.50697882 | BF4: 全 国 | BG4: 3151.75 | BH4: 233.68 | BI4: 90.46 | BJ4: 696.68 | BK4: 281.43 | BL4: 123.22 | BM4: 159.33 | BN4: =SUM(BH4:BM4)/BG4 -> 0.50283176 | BP4: 全 国 | BQ4: 2601.94 | BR4: 176.79 | BS4: 70.11 | BT4: 583.84 | BU4: 210.77 | BV4: 91.7 | BW4: 131.77 | BX4: =SUM(BR4:BW4)/BQ4 -> 0.48616801
A5: 北 京 | B5: 223.91 | C5: 6.04 | D5: 4.06 | E5: 99.64 | F5: 2.77 | G5: 0.53 | H5: 6.29 | I5: =SUM(C5:H5)/B5 -> 0.53293734 | K5: 172.36 | L5: 4.9 | M5: 4.39 | N5: 72.24 | O5: 2.78 | P5: 1.16 | Q5: 4.7 | R5: =SUM(L5:Q5)/K5 -> 0.52314922 | T5: 107.64 | U5: 2.98 | V5: 3.25 | W5: 58.26 | X5: 3.4 | Y5: 0.39 | Z5: 2.17 | AA5: =SUM(U5:Z5)/T5 -> 0.65449647 | AC5: 104.7 | AD5: 4.1 | AE5: 4.03 | AF5: 54.07 | AG5: 8.61 | AH5: 0.49 | AI5: 2.95 | AJ5: =SUM(AD5:AI5)/AC5 -> 0.70916905 | AL5: 104.71 | AM5: 2.92 | AN5: 6.07 | AO5: 40.47 | AP5: 11.41 | AQ5: 0.61 | AR5: 4.1 | AS5: =SUM(AM5:AR5)/AL5 -> 0.62630121 | AV5: 70.3 | AW5: 2.5 | AX5: 3.25 | AY5: 17.96 | AZ5: 10.35 | BA5: 0.46 | BB5: 2.57 | BC5: =SUM(AW5:BB5)/AV5 -> 0.52759602 | BF5: 北 京 | BG5: 61.99 | BH5: 0.89 | BI5: 3.24 | BJ5: 14.35 | BK5: 10.32 | BL5: 0.53 | BM5: 2.89 | BN5: =SUM(BH5:BM5)/BG5 -> 0.51976125 | BP5: 北 京 | BQ5: 54.66 | BR5: 1.62 | BS5: 2.57 | BT5: 16.03 | BU5: 7.09 | BV5: 0.32 | BW5: 2.71 | BX5: =SUM(BR5:BW5)/BQ5 -> 0.55506769
A6: 天 津 | B6: 202.13 | C6: 19.46 | D6: 7.45 | E6: 21.13 | F6: 61.72 | G6: 3.86 | H6: 4.58 | I6: =SUM(C6:H6)/B6 -> 0.58477218 | K6: 158.46 | L6: 16.46 | M6: 4.87 | N6: 18.08 | O6: 46.28 | P6: 4.65 | Q6: 2.71 | R6: =SUM(L6:Q6)/K6 -> 0.58721444 | T6: 101.71 | U6: 9.05 | V6: 4.5 | W6: 15.34 | X6: 31.34 | Y6: 2.62 | Z6: 2.28 | AA6: =SUM(U6:Z6)/T6 -> 0.64035001 | AC6: 85.88 | AD6: 3.91 | AE6: 5.28 | AF6: 15.36 | AG6: 26.33 | AH6: 1.21 | AI6: 1.93 | AJ6: =SUM(AD6:AI6)/AC6 -> 0.62901723 | AL6: 103.14 | AM6: 6.79 | AN6: 8.15 | AO6: 11.75 | AP6: 31.51 | AQ6: 1.5 | AR6: 2.75 | AS6: =SUM(AM6:AR6)/AL6 -> 0.60548769 | AV6: 60.84 | AW6: 4.04 | AX6: 5.2 | AY6: 7.34 | AZ6: 19.11 | BA6: 0.75 | BB6: 1.82 | BC6: =SUM(AW6:BB6)/AV6 -> 0.62886259 | BF6: 天 津 | BG6: 44.25 | BH6: 3.22 | BI6: 5.2 | BJ6: 6.41 | BK6: 8.33 | BL6: 0.47 | BM6: 1.45 | BN6: =SUM(BH6:BM6)/BG6 -> 0.56677966 | BP6: 天 津 | BQ6: 49.96 | BR6: 2.41 | BS6: 4.25 | BT6: 6.37 | BU6: 6.94 | BV6: 0.73 | BW6: 1.27 | BX6: =SUM(BR6:BW6)/BQ6 -> 0.4397518
A7: 河 北 | B7: 544.11 | C7: 26.52 | D7: 22.84 | E7: 74.8 | F7: 154.3 | G7: 5.1 | H7: 34.15 | I7: =SUM(C7:H7)/B7 -> 0.58390767 | K7: 444 | L7: 18.9 | M7: 18.79 | N7: 63.01 | O7: 114.7 | P7: 4.48 | Q7: 28.48 | R7: =SUM(L7:Q7)/K7 -> 0.55936937 | T7: 305.24 | U7: 14.91 | V7: 14.28 | W7: 53.85 | X7: 83.36 | Y7: 3.58 | Z7: 15.87 | AA7: =SUM(U7:Z7)/T7 -> 0.60886516 | AC7: 253.21 | AD7: 12.59 | AE7: 8.01 | AF7: 52.18 | AG7: 70.97 | AH7: 2.77 | AI7: 13.18 | AJ7: =SUM(AD7:AI7)/AC7 -> 0.63070179 | AL7: 257.84 | AM7: 13.66 | AN7: 12.3 | AO7: 49.27 | AP7: 73.98 | AQ7: 2.54 | AR7: 13.72 | AS7: =SUM(AM7:AR7)/AL7 -> 0.64175458 | AV7: 187.83 | AW7: 11.78 | AX7: 8.29 | AY7: 35.06 | AZ7: 51.96 | BA7: 2.03 | BB7: 10.8 | BC7: =SUM(AW7:BB7)/AV7 -> 0.63844966 | BF7: 河 北 | BG7: 146.45 | BH7: 10.89 | BI7: 5.32 | BJ7: 26.42 | BK7: 35.68 | BL7: 1.59 | BM7: 10.75 | BN7: =SUM(BH7:BM7)/BG7 -> 0.61898259 | BP7: 河 北 | BQ7: 117.95 | BR7: 10.17 | BS7: 3.27 | BT7: 20.85 | BU7: 29.11 | BV7: 1.54 | BW7: 6.62 | BX7: =SUM(BR7:BW7)/BQ7 -> 0.60669775
A8: 山 西 | B8: 452.98 | C8: 23.42 | D8: 43.07 | E8: 76.75 | F8: 50.38 | G8: 17.37 | H8: 10.73 | I8: =SUM(C8:H8)/B8 -> 0.48946973 | K8: 351.71 | L8: 20.52 | M8: 41.54 | N8: 57.98 | O8: 39.74 | P8: 14.19 | Q8: 9.72 | R8: =SUM(L8:Q8)/K8 -> 0.52227688 | T8: 255.35 | U8: 12.69 | V8: 34.25 | W8: 47.86 | X8: 29.3 | Y8: 10.41 | Z8: 6.68 | AA8: =SUM(U8:Z8)/T8 -> 0.55292735 | AC8: 217.07 | AD8: 12.96 | AE8: 29.35 | AF8: 45.16 | AG8: 22.45 | AH8: 11.09 | AI8: 5.9 | AJ8: =SUM(AD8:AI8)/AC8 -> 0.58465011 | AL8: 227.12 | AM8: 12.57 | AN8: 36.15 | AO8: 43.03 | AP8: 27.87 | AQ8: 11.94 | AR8: 5.14 | AS8: =SUM(AM8:AR8)/AL8 -> 0.60188447 | AV8: 168.73 | AW8: 11.53 | AX8: 25.03 | AY8: 31.98 | AZ8: 24.48 | BA8: 9.49 | BB8: 4.75 | BC8: =SUM(AW8:BB8)/AV8 -> 0.63569016 | BF8: 山 西 | BG8: 117.49 | BH8: 7.75 | BI8: 18.15 | BJ8: 25.75 | BK8: 15.21 | BL8: 7.21 | BM8: 3.92 | BN8: =SUM(BH8:BM8)/BG8 -> 0.66380117 | BP8: 山 西 | BQ8: 99.09 | BR8: 7.07 | BS8: 14.39 | BT8: 24.04 | BU8: 11.13 | BV8: 4.17 | BW8: 4.4 | BX8: =SUM(BR8:BW8)/BQ8 -> 0.65798769
A9: 内蒙古 | B9: 352.12 | C9: 29.33 | D9: 14.5 | E9: 119.26 | F9: 36.77 | G9: 16.19 | H9: 10.23 | I9: =SUM(C9:H9)/B9 -> 0.64262183 | K9: 261.49 | L9: 13.28 | M9: 10.19 | N9: 97.17 | O9: 26.38 | P9: 18.93 | Q9: 8.01 | R9: =SUM(L9:Q9)/K9 -> 0.66526445 | T9: 191.91 | U9: 13.77 | V9: 5.96 | W9: 65.85 | X9: 16.55 | Y9: 12.79 | Z9: 8 | AA9: =SUM(U9:Z9)/T9 -> 0.64050857 | AC9: 157.32 | AD9: 6.43 | AE9: 2.29 | AF9: 68.45 | AG9: 17.27 | AH9: 9.27 | AI9: 5.52 | AJ9: =SUM(AD9:AI9)/AC9 -> 0.69431732 | AL9: 152.88 | AM9: 5.39 | AN9: 3.15 | AO9: 79.07 | AP9: 11.71 | AQ9: 8.86 | AR9: 5.36 | AS9: =SUM(AM9:AR9)/AL9 -> 0.74267399 | AV9: 100.47 | AW9: 4.25 | AX9: 1.53 | AY9: 47.88 | AZ9: 6.17 | BA9: 6.52 | BB9: 3.27 | BC9: =SUM(AW9:BB9)/AV9 -> 0.69294317 | BF9: 内蒙古 | BG9: 76.31 | BH9: 2.83 | BI9: 0.74 | BJ9: 41.14 | BK9: 1.72 | BL9: 4.65 | BM9: 2.78 | BN9: =SUM(BH9:BM9)/BG9 -> 0.70580527 | BP9: 内蒙古 | BQ9: 59.51 | BR9: 2.67 | BS9: 0.61 | BT9: 31.25 | BU9: 1.88 | BV9: 3.14 | BW9: 2.26 | BX9: =SUM(BR9:BW9)/BQ9 -> 0.702571
A10: 辽 宁 | B10: 480.77 | C10: 27.85 | D10: 31.58 | E10: 58.83 | F10: 100.69 | G10: 20.79 | H10: 28.03 | I10: =SUM(C10:H10)/B10 -> 0.55696071 | K10: 385.24 | L10: 19.3 | M10: 23 | N10: 51.39 | O10: 80.86 | P10: 19.55 | Q10: 19.97 | R10: =SUM(L10:Q10)/K10 -> 0.55567958 | T10: 273.18 | U10: 21.81 | V10: 8.04 | W10: 42.12 | X10: 59.68 | Y10: 14.21 | Z10: 14.86 | AA10: =SUM(U10:Z10)/T10 -> 0.58833004 | AC10: 227.76 | AD10: 14.04 | AE10: 8.55 | AF10: 37.88 | AG10: 47.84 | AH10: 10.99 | AI10: 12.43 | AJ10: =SUM(AD10:AI10)/AC10 -> 0.57837197 | AL10: 230.3 | AM10: 13.38 | AN10: 9.21 | AO10: 35.29 | AP10: 50.17 | AQ10: 10.69 | AR10: 11.31 | AS10: =SUM(AM10:AR10)/AL10 -> 0.56469822 | AV10: 163.94 | AW10: 11.01 | AX10: 6.19 | AY10: 27.28 | AZ10: 32.44 | BA10: 9.18 | BB10: 9.06 | BC10: =SUM(AW10:BB10)/AV10 -> 0.58045626 | BF10: 辽 宁 | BG10: 134.44 | BH10: 10.08 | BI10: 8.38 | BJ10: 23.58 | BK10: 23.73 | BL10: 7.17 | BM10: 6.7 | BN10: =SUM(BH10:BM10)/BG10 -> 0.59238322 | BP10: 辽 宁 | BQ10: 119.91 | BR10: 9.76 | BS10: 5.71 | BT10: 22.89 | BU10: 20.94 | BV10: 5.69 | BW10: 6.11 | BX10: =SUM(BR10:BW10)/BQ10 -> 0.59294471
A11: 吉 林 | B11: 198.04 | C11: 9.12 | D11: 1.29 | E11: 44.31 | F11: 5.71 | G11: 7.04 | H11: 17.49 | I11: =SUM(C11:H11)/B11 -> 0.42900424 | K11: 149.68 | L11: 7.58 | M11: 1.05 | N11: 33.36 | O11: 6.56 | P11: 6.92 | Q11: 12.15 | R11: =SUM(L11:Q11)/K11 -> 0.45176376 | T11: 96.37 | U11: 5.66 | V11: 0.74 | W11: 18.58 | X11: 7.15 | Y11: 2.64 | Z11: 7.7 | AA11: =SUM(U11:Z11)/T11 -> 0.44069731 | AC11: 100.69 | AD11: 5.35 | AE11: 0.58 | AF11: 17 | AG11: 7.43 | AH11: 1.99 | AI11: 6.81 | AJ11: =SUM(AD11:AI11)/AC11 -> 0.38891648 | AL11: 84.01 | AM11: 4.61 | AN11: 0.7 | AO11: 18.14 | AP11: 9.02 | AQ11: 1.56 | AR11: 5.06 | AS11: =SUM(AM11:AR11)/AL11 -> 0.46530175 | AV11: 66.25 | AW11: 3.81 | AX11: 0.24 | AY11: 14.06 | AZ11: 5.58 | BA11: 0.15 | BB11: 3.11 | BC11: =SUM(AW11:BB11)/AV11 -> 0.40679245 | BF11: 吉 林 | BG11: 54.64 | BH11: 4.61 | BI11: 0.12 | BJ11: 13.42 | BK11: 4.04 | BL11: 0.26 | BM11: 3.14 | BN11: =SUM(BH11:BM11)/BG11 -> 0.46833821 | BP11: 吉 林 | BQ11: 47.7 | BR11: 4.25 | BS11: 0.44 | BT11: 12.26 | BU11: 3.43 | BV11: 0.5 | BW11: 2.54 | BX11: =SUM(BR11:BW11)/BQ11 -> 0.49098532
A12: 黑龙江 | B12: 151.8 | C12: 5.7 | D12: 8.53 | E12: 43.03 | F12: 7.72 | G12: 0.97 | H12: 5.47 | I12: =SUM(C12:H12)/B12 -> 0.47048748 | K12: 117.44 | L12: 4.48 | M12: 6.91 | N12: 34.59 | O12: 4.69 | P12: 0.72 | Q12: 2.98 | R12: =SUM(L12:Q12)/K12 -> 0.46295981 | T12: 72.12 | U12: 3.56 | V12: 3.41 | W12: 28.14 | X12: 4.77 | Y12: 0.48 | Z12: 1.99 | AA12: =SUM(U12:Z12)/T12 -> 0.58721575 | AC12: 58.89 | AD12: 1.43 | AE12: 3.64 | AF12: 27.21 | AG12: 2.61 | AH12: 0.29 | AI12: 1.31 | AJ12: =SUM(AD12:AI12)/AC12 -> 0.61962982 | AL12: 62 | AM12: 1.31 | AN12: 4.49 | AO12: 24.71 | AP12: 3.68 | AQ12: 0.53 | AR12: 1.28 | AS12: =SUM(AM12:AR12)/AL12 -> 0.58064516 | AV12: 52.5 | AW12: 1.76 | AX12: 6.18 | AY12: 21.49 | AZ12: 2.7 | BA12: 0.46 | BB12: 1.29 | BC12: =SUM(AW12:BB12)/AV12 -> 0.64533333 | BF12: 黑龙江 | BG12: 33.92 | BH12: 1.3 | BI12: 1.88 | BJ12: 12.99 | BK12: 1.56 | BL12: 0.36 | BM12: 1.6 | BN12: =SUM(BH12:BM12)/BG12 -> 0.58048349 | BP12: 黑龙江 | BQ12: 45.06 | BR12: 0.76 | BS12: 4.06 | BT12: 14.2 | BU12: 1.19 | BV12: 0.3 | BW12: 1.3 | BX12: =SUM(BR12:BW12)/BQ12 -> 0.4840213
A13: 上 海 | B13: 248.16 | C13: 24.07 | D13: 6.46 | E13: 25.68 | F13: 17.63 | G13: 5.21 | H13: 6.67 | I13: =SUM(C13:H13)/B13 -> 0.34542231 | K13: 208.47 | L13: 20.39 | M13: 5.49 | N13: 24.22 | O13: 20.32 | P13: 4.89 | Q13: 5.34 | R13: =SUM(L13:Q13)/K13 -> 0.38686622 | T13: 122.78 | U13: 16.43 | V13: 3.7 | W13: 19.53 | X13: 15.7 | Y13: 3.3 | Z13: 3.56 | AA13: =SUM(U13:Z13)/T13 -> 0.50676006 | AC13: 136.99 | AD13: 22.38 | AE13: 4.89 | AF13: 17.06 | AG13: 18.11 | AH13: 2.53 | AI13: 3.76 | AJ13: =SUM(AD13:AI13)/AC13 -> 0.50171545 | AL13: 167.95 | AM13: 24.34 | AN13: 8.35 | AO13: 17.94 | AP13: 31.63 | AQ13: 4.22 | AR13: 4.68 | AS13: =SUM(AM13:AR13)/AL13 -> 0.54278059 | AV13: 119.94 | AW13: 16.77 | AX13: 3.59 | AY13: 8.59 | AZ13: 20.8 | BA13: 2.98 | BB13: 4.2 | BC13: =SUM(AW13:BB13)/AV13 -> 0.47465399 | BF13: 上 海 | BG13: 110.76 | BH13: 15.77 | BI13: 4.41 | BJ13: 6.26 | BK13: 17.71 | BL13: 1.98 | BM13: 4.04 | BN13: =SUM(BH13:BM13)/BG13 -> 0.45296136 | BP13: 上 海 | BQ13: 91.02 | BR13: 9.02 | BS13: 3.5 | BT13: 4.5 | BU13: 12.41 | BV13: 1.56 | BW13: 3.41 | BX13: =SUM(BR13:BW13)/BQ13 -> 0.37793891
